Workbook
Name SegmentaçãodeDados_Área: #N/A
Name SegmentaçãodeDados_Peso: #N/A
Name _ftn1: 'Formulário de Conformidade'!#REF!
Name _ftnref1: 'Formulário de Conformidade'!#REF!

Sheet Formulário de Perfil
B3: QTDE | C3: DADOS BÁSICOS | D3: Tooltip | E3: TIPO | F3: Opções
B4: 1 | C4: DB1. Nome da pessoa jurídica - Razão Social: | D4: Informar a denominação pela qual a pessoa jurídica está registrada no Cadastro Nacional da Pessoa Jurídica. | E4: Texto | F4: JDS ENGENHARIA E CONSULTORIA LTDA
B5: 2 | C5: DB2. E-mail institucional da área de integridade: | D5: Informar o e-mail da área ou pessoa responsável pelo programa de integridade. Indicar e-mail institucional, evitando-se conta de uso pessoal. Este e-mail poderá ser utilizado pela CGU para dúvidas, informes, pedidos de esclarecimentos etc. | E5: Texto (máscara: e-mail) | F5: E-mail: jdseng@jdseng.com.br
B6: 3 | C6: DB3. CNPJ: | D6: Informar o CNPJ da pessoa jurídica. | E6: Texto (máscara: CNPJ) | F6: 40.376.139/0001-59
B7: 4 | C7: DB4. Representante do programa de integridade: | D7: Informar o nome do representante da pessoa jurídica para ser comunicado em relação à avaliação do programa de integridade. | E7: Texto | F7: Yuri Renan Procopio dos Santos Pinto Zolet
B8: 5 | C8: DB5. Cargo do representante: | D8: Informar o cargo do representante da pessoa jurídica. | E8: Texto | F8: Oficial de Compliance
B9: 6 | C9: DB6. Telefone do representante: | D9: Informar o telefone do representante da pessoa jurídica. | E9: Texto (máscara: telefone) | F9: (21) 8899-6848
C10: ESTRUTURA E ATIVIDADE ECONÔMICA
B11: 1 | C11: EA1. Qual a atividade econômica principal? | D11: Selecionar a opção que se refere a sua atividade econômica principal. A pessoa jurídica deverá observar os dois primeiros dígitos do CNAE e correlacioná-los com alguma das atividades descritas na lista. Exemplo: CNAE: 64.62-0-00 Atividade a ser selecionada na lista: (64 a 66) | E11: Lista Seleção Única | F11: (41 a 43) Construção CÓDIGO DE ATIVIDADES ECONÔMICAS (CAE): 2.60.39.8 - SUPERVISÃO DE OBRAS E DE SERVIÇOS DE ENGENHARIA 2.26.29.7 - PROJETOS E ESTUDOS DE ENGENHARIA 2.61.28.9 - ENGENHARIA, SERVIÇOS DE 2.27.12.9 - CONSULTORIA TÉCNICA 2.26.51.3 - ANÁLISE E PROGRAMAÇÃO DE SISTEMAS 2.27.15.3 - ASSESSORIA TÉCNICA
B12: 2 | C12: EA2. Qual o porte da pessoa jurídica?1 | D12: Critério para a definição do porte conf. faturamento anual: - Microempresa: até R$ 360 mil - Empresa de Pequeno Porte: de R$ 360 mil até R$ 4,8 milhões - Média empresa: de R$ 4,8 milhões até R$ 300 milhões - Grande empresa: acima de R$ 300 milhões. | E12: Lista Seleção Única | F12: Micro e Pequeno porte (de acordo com o Estatuto da Micro e Pequena Empresa) Médio Grande
B13: 3 | C13: EA3. Qual o faturamento anual? | D13: Selecionar a opção que se refere ao faturamento estimado, obtido pela pessoa jurídica a cada ano. | E13: Lista Seleção Única | F13: <= R$ 360 mil > R$ 360 mil e <= R$ 4,8 milhões > R$ 4,8 milhões e <= R$ 16 milhões > R$ 16 milhões e <= R$ 90 milhões > R$ 90 milhões e <= R$ 300 milhões > R$ 300 milhões e <= R$ 1 bilhão > R$ 1 bilhão
B14: 4 | C14: EA4. Descrever a estrutura organizacional da pessoa jurídica (Ex.: presidência, conselhos, comitês, diretorias etc.): | D14: Informar a estrutura organizacional, apresentando breve resumo das instâncias que a compõem, suas atribuições, membros e as relações de hierarquia/subordinação existentes. | E14: Texto Longo | F14: JDS Engenharia e Consultoria Ltda., ao longo de mais de três décadas, é uma empresa que presta serviços técnicos especializados, notadamente nas áreas de elaboração de estudos de viabilidade, desenvolvimento de projetos, supervisão e gerenciamento de obras, com atuação destacada em empreendimentos de infraestrutura. E também atua na área de consultoria técnica especializada. Em termos de estrutura a empresa possui: uma Diretoria Executiva; as Diretorias Técnicas e Administrativa; e Áreas Técnicas Operacionais.
B15: 5 | C15: EA5. Integra algum grupo econômico? 2 | D15: Selecionar “Sim” ou “Não”, conforme o caso. | E15: Sim/Não | F15: Não
B16: 6 | C16: EA5.1. Informar o nome do grupo econômico: | D16: Informar o nome do grupo econômico ao qual a pessoa jurídica pertence. | E16: Texto Longo | F16: Não se aplica.
B17: 7 | C17: EA5.2. Informar se o programa de integridade se aplica a mais de uma pessoa jurídica do grupo e para quais pessoas jurídicas se aplica: | D17: Informar para quais outras pessoas jurídicas do grupo econômico o programa de integridade é aplicado. | E17: Texto Longo | F17: Não se aplica.
B18: 8 | C18: EA5.3. Informar se é controladora, controlada, coligada, subsidiária, etc., indicando as principais pessoas jurídicas que integram o grupo e os países em que atuam: | D18: Informar a condição da pessoa jurídica no seu grupo econômico, bem como citar as principais pessoa jurídicas que integram esse grupo e os países em que elas exercem atividade. | E18: Texto Longo | F18: Não se aplica.
B19: 9 | C19: EA6. Realizou, nos últimos 24 meses, operações societárias envolvendo outras pessoas jurídicas (Ex.: fusão, incorporação etc.)?3 4 | D19: Selecionar “Sim” ou “Não”, conforme o caso. As operações societárias incluem: fusões, incorporações, aquisições, cisões etc. | E19: Sim/Não | F19: Não.
B20: 10 | C20: EA6.1. Descrever as operações societárias realizadas: | D20: Ex.: data, tipo de operação, pessoas jurídicas envolvidas, ações relacionadas à operação, alterações na estrutura societária e de mercado das pessoas jurídicas, aprovação pelos órgãos de fiscalização e de defesa econômica etc. | E20: Texto Longo | F20: Não se aplica.
B21: 11 | C21: EA7. Qual o percentual de colaboradores que possuem acesso à internet, fornecido pela pessoa jurídica, no local de trabalho? | D21: Selecionar a opção que se refere ao percentual de colaboradores com acesso à internet no local de trabalho. | E21: Lista Seleção Única | F21: 0 % - Nenhum possui acesso à internet Entre 1% e 20% Entre 21% e 40% Entre 41% e 60% Entre 61% e 80% Entre 81% e 100%
B22: 12 | C22: EA8. Quantos colaboradores possui? | D22: Informar a quantidade de colaboradores que a pessoa jurídica possui, incluindo funcionários, terceirizados, estagiários e aprendizes. | E22: Número | F22: Conta atualmente com 38 (trinta e oito) emprega-dos sob o regime da CLT e 24 (vinte e quatro) colaboradores contratados na modalidade de Pessoa Jurídica.
C23: INTERAÇÃO COM PODER PÚBLICO
B24: 1 | C24: IP1. A pessoa jurídica se submete à regulação de agência/órgão governamental?5 | D24: Selecionar “Sim” ou “Não”, conforme o caso. | E24: Sim/Não | F24: Não.
B25: 2 | C25: IP1.1. Informar quais são as agências/órgãos reguladores a que a pessoa jurídica está submetida: | D25: Informar as agências/órgãos governamentais responsáveis por regular as atividades exercidas pela pessoa jurídica. | E25: Texto Longo | F25: Não se aplica.
B26: 3 | C26: IP2. Em relação à obtenção de licenças, autorizações e permissões governamentais, como poderia ser classificada a situação da pessoa jurídica? | D26: Selecionar a opção que se refere à situação da pessoa jurídica com relação às licenças, autorizações e permissões governamentais. | E26: Lista Seleção Única | F26: a) Não necessita de licenças, autorizações ou permissões no exercício de suas atividades (exceto licenças básicas para funcionamento da pessoa jurídica, como alvarás de funcionamento e de vistoria do corpo de bombeiros).
B27: 4 | C27: IP2.1. Descrever as licenças, autorizações e permissões das quais a pessoa jurídica necessite: | D27: Informar as licenças, autorizações e permissões das quais a pessoa jurídica necessite no exercício de suas atividades, incluindo licenças básicas para funcionamento. | E27: Texto Longo | F27: Não se aplica.
B28: 5 | C28: IP3. Em relação à participação em licitações públicas, como poderia ser classificada a situação da pessoa jurídica? | D28: Selecionar a opção que se refere à situação da pessoa jurídica com relação a sua participação em licitações públicas. | E28: Lista Seleção Única | F28: Participa com frequência de licitações.
B29: 6 | C29: IP4. Em relação à celebração de contratos com a Administração Pública, como poderia ser classificada a situação da pessoa jurídica? | D29: Selecionar a opção que se refere à situação da pessoa jurídica com relação à celebração de contratos com a Administração Pública. | E29: Lista Seleção Única | F29: Celebra com frequência contratos com a Administração Pública.
B30: 7 | C30: IP5. Qual das faixas mais se aproxima do percentual médio do faturamento proveniente de contratos firmados com o poder público? | D30: Selecionar a opção que se refere ao % que os contratos representam do faturamento total da pessoa jurídica. | E30: Lista Seleção Única | F30: 1% a 20% 21% a 40% 41% a 60% 61% a 80% 81% a 100%
B31: 8 | C31: IP6. Utiliza intermediários no contato com a Administração Pública para execução de contratos administrativos, obtenção de autorizações, licenças e permissões, protocolo de documentos, desembaraço aduaneiro etc.?6 | D31: Selecionar “Sim” ou “Não”, conforme o caso. Intermediários incluem: consultores, advogados, assessores, despachantes, procuradores etc. | E31: Sim/Não
B32: 9 | C32: IP6.1. Descrever como ocorreu a utilização de intermediários no contato com a Administração Pública por parte da pessoa jurídica: | D32: Ex.: data, terceiro contratado, objeto, órgão ou entidade pública relacionada, atividades desempenhadas etc. | E32: Texto Longo
B33: 10 | C33: IP7. A pessoa jurídica subcontratou atividades relacionadas à execução de contratos administrativos?7 | D33: Selecionar “Sim” ou “Não”, conforme o caso. Entende-se por “subcontratação” a situação em que a pessoa jurídica contrata um terceiro para executar determinada parcela do contrato administrativo. | E33: Sim/Não
B34: 11 | C34: IP7.1. Explicar como ocorreram as subcontratações de atividades relacionadas à execução de contratos administrativos por parte da pessoa jurídica: | D34: Ex.: data, contrato administrativo, terceiro e objeto subcontratado, aprovação pelo órgão ou entidade pública etc. | E34: Texto Longo
C35: DOAÇÕES E PATROCÍNIOS
B36: 1 | C36: DP1. A pessoa jurídica realizou patrocínios esportivos ou culturais, nos últimos 24 meses? | D36: Selecionar “Sim” ou “Não”, conforme o caso. | E36: Sim/Não | F36: Não informado.
B37: 2 | C37: DP2. A pessoa jurídica efetuou doações, nos últimos 24 meses? | D37: Selecionar “Sim” ou “Não”, conforme o caso. | E37: Sim/Não | F37: Não informado.
C38: PRÁTICAS SOCIOAMBIENTAIS
B39: 1 | C39: PS1. A atividade da pessoa jurídica envolve potencial de dano ao meio ambiente?8 | D39: Selecionar “Sim” ou “Não”, conforme o caso. | E39: Sim/Não | F39: Sim
B40: 2 | C40: PS1.1 Apresentar justificativas por entender que não possui atividades que podem causar impactos ambientais: | D40: Explicar os motivos que levam a pessoa jurídica a concluir que suas atividades não geram impactos ambientais, tais como: localização, natureza das operações, uso mínimo de recursos naturais etc., e outras avaliações que fundamentem esse entendimento. | E40: Texto Longo
C41: PROGRAMA DE INTEGRIDADE
B42: 1 | C42: PI1. Quando entende que seu programa de integridade foi formalmente instituído? | D42: Selecionar a opção que se refere ao tempo decorrido desde o ano de instituição do programa de integridade, conforme a existência dos seguintes elementos básicos: Código de Ética/Conduta; Canal de Denúncias; e Área Específica ou Pessoa Responsável pelo programa. | E42: Lista Seleção Única | F42: Em até 1 ano Entre 1 e 3 anos Entre 3 e 5 anos Acima de 5 anos
...

Sheet Formulário de Conformidade
B2: FORMULÁRIO DE CONFORMIDADE
C3: Processo: 00190.104729/2021-05
C4: Pessoa Jurídica: 40.376.139/0001-59 - JDS
C5: Avaliado por/data:
C6: Revisado por/data:
B8: Área | C8: Tipo | D8: Item | E8: Tipo de Resposta | F8: Nível | G8: Valor | H8: Avaliação | I8: Pont. Resdist. | J8: Pontuação | K8: Evidência | L8: Análise | M8: Vinculação Condicional | N8: Distribuição "Não se aplica"
B9: I | C9: Área | D9: Área I - Comprometimento da Alta Direção da Pessoa jurídica
B10: I | C10: Grupo | D10: 1. Adoção de critérios de integridade para seleção e remuneração de candidatos a cargos da alta direção
B11: I | C11: Questão | D11: 1.1 A pessoa jurídica possui critérios de integridade formalizados para seleção dos candidatos aos cargos da alta direção? Se sim, anexar documentos que comprovem a existência dos critérios de integridade para seleção e informar os cargos a que são aplicados, a forma como os critérios são considerados e os responsáveis por sua avaliação. | E11: Sim, Não | F11: QN2 | G11: 15 | H11: Não | J11: =IF(H11="Sim",G11, IF(H11="Parcialmente",G11/2, IF(OR(H11="Não",H11="Não se aplica"),0,""))) +IF(OR(H11="Sim",H11="Parcialmente"),Tabela1[[#This Row],[Pont. Resdist.]],0) | K11: Ausência de documento | L11: NÃO ATENDIDA. • Análise inicial (resposta anterior: Não): Não foram localizados critérios formalizados de integridade para seleção de candidatos à alta direção. A documentação não apresenta qualquer política de recursos humanos nesse sentido. • Complementação (nova documentação): Não foi apresentada política de RH com critérios de integridade formalizados para seleção da alta direção. Lacuna não sanada.
B12: I | C12: Questão | D12: 1.2 A pessoa jurídica aplicou critérios de integridade para seleção dos ocupantes de cargos da alta direção contratados nos últimos 24 meses? Se sim, anexar documentos que comprovem a aplicação dos critérios de integridade para seleção. | E12: Sim, Não, Não se aplica | F12: QN5 | G12: 18 | H12: Não se Aplica | J12: =IF(H12="Sim",G12, IF(H12="Parcialmente",G12/2, IF(OR(H12="Não",H12="Não se aplica"),0,""))) +IF(OR(H12="Sim",H12="Parcialmente"),Tabela1[[#This Row],[Pont. Resdist.]],0) | K12: Doc 01 - Estatuto Social | L12: NÃO SE APLICA (mantida da 1ª análise). Empresa sem conselho de administração ou fiscal formalmente constituído. | M12: Grupo: ESTRUTURA E ATIVIDADE ECONÔMICA Questão: Qual o porte da pessoa jurídica? Alternativa: Micro e Pequeno porte (de acordo com o Estatuto da Micro e Pequena pessoa jurídica) | N12: Distribuir 2,25 pontos para cada uma das questões (8): 1.1 2.1 2.3 3.1 3.2.1 3.2.2 3.2.3 3.3
B13: I | C13: Questão | D13: 1.3 A pessoa jurídica possui política de remuneração variável para os membros da alta direção condicionada ao atingimento de metas de desempenho relacionadas aos indicadores de aplicação ao programa de integridade? Se sim, anexar a política de remuneração que comprova a existência dessa regra e descrever como ela é aplicada. | E13: Sim, Não, Não se aplica | F13: QN2 | G13: 15 | H13: Não se Aplica | J13: =IF(H13="Sim",G13, IF(H13="Parcialmente",G13/2, IF(OR(H13="Não",H13="Não se aplica"),0,""))) +IF(OR(H13="Sim",H13="Parcialmente"),Tabela1[[#This Row],[Pont. Resdist.]],0) | K13: Ausência de documento | L13: NÃO SE APLICA (mantida da 1ª análise). Não foram apresentadas evidências de política de remuneração variável vinculada a metas de integridade. A estrutura da empresa de médio porte não contempla este mecanismo. | M13: Grupo: ESTRUTURA E ATIVIDADE ECONÔMICA Questão: Qual o porte da pessoa jurídica? Alternativa: Micro e Pequeno porte (de acordo com o Estatuto da Micro e Pequena pessoa jurídica) | N13: Distribuir pontos para cada uma das questões (8): 1.1 = 1,87 2.1 = 1,88 2.3 = 1,88 3.1 = 1,88 3.2.1 = 1,87 3.2.2 = 1,87 3.2.3 = 1,87 3.3 = 1,88
B14: I | C14: Grupo | D14: 2. Envolvimento da alta direção na implementação e supervisão do programa de integridade
B15: I | C15: Questão | D15: 2.1 A aprovação das principais políticas relacionadas ao programa de integridade é feita pelas mais elevadas instâncias decisórias da pessoa jurídica? Se sim, anexar documentos que comprovem a aprovação das principais políticas relacionadas ao programa de integridade pela alta direção. | E15: Sim, Não | F15: QN1 | G15: 20 | H15: Sim | J15: =IF(H15="Sim",G15, IF(H15="Parcialmente",G15/2, IF(OR(H15="Não",H15="Não se aplica"),0,""))) +IF(OR(H15="Sim",H15="Parcialmente"),Tabela1[[#This Row],[Pont. Resdist.]],0) | K15: Cód_Etica.pdf (Doc 12.1, ass. digital 11/08/2025); Políticas_Internas.pdf (Doc 12.5, aprovadas 13/03/2026) | L15: QUESTÃO CRÍTICA - As políticas foram aprovadas e assinadas, mas não há registros documentados de reunião deliberativa formal da alta direção aprovando o conjunto das políticas de integridade. O Código de Ética (V.01.2025) foi assinado digitalmente em 11/08/2025 e as Políticas Internas foram aprovadas em 13/03/2026. Como não há o quesito do julgamento parcial, opta-se pelo Sim.
B16: I | C16: Questão | D16: 2.2 A pessoa jurídica possui em sua estrutura de governança órgão colegiado (como comitê ou conselho de ética) para deliberar sobre temas de ética e integridade, que contam com a participação de membros da alta direção? Se sim, anexar documentos que comprovem a existência do órgão colegiado e a participação dos membros da alta direção em sua composição. | E16: Sim, Não, Não se aplica | F16: QN2 | G16: 15 | H16: Não se Aplica | J16: =IF(H16="Sim",G16, IF(H16="Parcialmente",G16/2, IF(OR(H16="Não",H16="Não se aplica"),0,""))) +IF(OR(H16="Sim",H16="Parcialmente"),Tabela1[[#This Row],[Pont. Resdist.]],0) | K16: Doc 01 - Estatuto Social | L16: Empresa sem órgão colegiado (conselho/comitê de integridade). | M16: Grupo: ESTRUTURA E ATIVIDADE ECONÔMICA Questão: Qual o porte da pessoa jurídica? Alternativa: Micro e Pequeno porte (de acordo com o Estatuto da Micro e Pequena pessoa jurídica) | N16: Distribuir pontos para cada uma das questões (8): 1.1 = 1,87 2.1 = 1,88 2.3 = 1,88 3.1 = 1,88 3.2.1 = 1,87 3.2.2 = 1,87 3.2.3 = 1,87 3.3 = 1,88
B17: I | C17: Questão | D17: 2.3 A alta direção da pessoa jurídica supervisiona, diretamente ou por intermédio de órgão colegiado do qual ela participe, a implantação e a aplicação do programa de integridade, por meio do recebimento e avaliação de relatórios periódicos de acompanhamento das atividades relacionadas ao programa de integridade? | E17: Sim, Não, Parcialmente | F17: QN5 | G17: 18 | H17: Sim | J17: =IF(H17="Sim",G17, IF(H17="Parcialmente",G17/2, IF(OR(H17="Não",H17="Não se aplica"),0,""))) +IF(OR(H17="Sim",H17="Parcialmente"),Tabela1[[#This Row],[Pont. Resdist.]],0) | K17: 1ª análise: Rel_Conformidade.pdf (Doc 12, 31/03/2026) Documentação complementar: Procedimento de Monitoramento Contínuo do PI V.01.2026; Termo de Designação do Oficial de Compliance, 07/07/2026; Matriz de Riscos de Integridade V.01/V.02.2026 (Termo de Aprovação da Diretoria, 24/03 e 30/07/2026) | L17: ATENDIDA — superada com a documentação complementar. • Análise inicial (resposta anterior: Parcialmente): Existe Relatório de Conformidade emitido em 31/03/2026 (Rel_Conformidade.pdf), mas não há evidências de supervisão periódica formalizada pela alta direção com reuniões ou relatórios recorrentes de acompanhamento do PI. • Complementação (nova documentação): O Procedimento de Monitoramento Contínuo prevê relatórios trimestrais/anuais à Diretoria; o Termo de Designação garante participação do Compliance em reuniões da Diretoria; e a Matriz de Riscos foi aprovada pela Diretoria — evidenciando supervisão periódica formalizada pela alta direção.
B18: I | C18: Grupo | D18: 3. Apoio visível e inequívoco da alta direção ao programa de integridade, incluindo a destinação de recursos adequados
B19: I | C19: Questão | D19: 3.1 Os membros da alta direção, individualmente, manifestam publicamente apoio ao programa de integridade? Se sim, anexar documentos e/ou indicar, no campo correspondente, link em que seja possível visualizar as manifestações de apoio ao programa de integridade por membros da alta direção. | E19: Sim, Não | F19: QN1 | G19: 20 | H19: Sim | J19: =IF(H19="Sim",G19, IF(H19="Parcialmente",G19/2, IF(OR(H19="Não",H19="Não se aplica"),0,""))) +IF(OR(H19="Sim",H19="Parcialmente"),Tabela1[[#This Row],[Pont. Resdist.]],0) | K19: 1ª análise: Doc 12.2; Doc 12.4 Documentação complementar: E-mails da Diretoria (João Darous) a todos os colaboradores, 02 e 17/07/2026 | L19: ATENDIDA — superada com a documentação complementar. • Análise inicial (resposta anterior: Não): Não foram localizadas manifestações públicas pessoais dos membros da alta direção (João Darous) em apoio ao Programa de Integridade. As comunicações sobre integridade foram emitidas pelo Oficial de Compliance (Yuri Renan), e não diretamente pela direção. • Complementação (nova documentação): Os e-mails de 02 e 17/07/2026, assinados pessoalmente pelo sócio-administrador João Darous e enviados a todos os colaboradores, manifestam apoio pessoal e expresso ao Programa de Integridade, suprindo a lacuna apontada.
B20: I | C20: Agrupadora | D20: 3.2 As manifestações de apoio ao programa de integridade por membros da alta direção:
B21: I | C21: Questão | D21: 3.2.1 são feitas de forma periódica e divulgadas por diferentes meios para alcançar o público interno e externo da pessoa jurídica em toda sua diversidade? Se sim, demonstrar a medida em que as manifestações de apoio ao programa de integridade ocorreram de forma periódica e direcionadas aos diferentes públicos da entidade. | E21: Sim, Não, Parcialmente | F21: QN3 | G21: 5 | H21: Parcialmente | J21: =IF(H21="Sim",G21, IF(H21="Parcialmente",G21/2, IF(OR(H21="Não",H21="Não se aplica"),0,""))) +IF(OR(H21="Sim",H21="Parcialmente"),Tabela1[[#This Row],[Pont. Resdist.]],0) | K21: 1ª análise: (sem documento) Documentação complementar: E-mails da Diretoria (João Darous) a todos os colaboradores, 02 e 17/07/2026; Calendário de Comunicações 2026 | L21: PARCIALMENTE ATENDIDA. • Análise inicial (resposta anterior: Não): Não foram identificadas comunicações formais periódicas do Diretor-Presidente sobre integridade. • Complementação (nova documentação): O Calendário de Comunicações 2026 e os e-mails da Diretoria evidenciam manifestações por diferentes meios; a periodicidade está prevista, mas parte das ações ainda consta como PREVISTA (execução em curso).
B22: I | C22: Questão | D22: 3.2.2 expressam uma mensagem de incentivo à adoção de uma conduta ética, seguindo os ditames do programa de integridade? Se sim, demonstrar a medida em que as manifestações de apoio ao programa de integridade expressaram o compromisso com os temas. | E22: Sim, Não | F22: QN3 | G22: 5 | H22: Sim | J22: =IF(H22="Sim",G22, IF(H22="Parcialmente",G22/2, IF(OR(H22="Não",H22="Não se aplica"),0,""))) +IF(OR(H22="Sim",H22="Parcialmente"),Tabela1[[#This Row],[Pont. Resdist.]],0) | K22: 1ª análise: (sem documento) Documentação complementar: E-mails da Diretoria (João Darous) a todos os colaboradores, 02 e 17/07/2026 | L22: ATENDIDA — superada com a documentação complementar. • Análise inicial (resposta anterior: Não): Sem manifestações individuais do Diretor-Presidente sobre conduta ética ou mensagens de incentivo. • Complementação (nova documentação): O e-mail da Diretoria expressa mensagem clara de incentivo à conduta ética e ao uso do canal de denúncias.
B23: I | C23: Questão | D23: 3.2.3 expressam o compromisso da alta direção com o combate ao preconceito, à discriminação e ao assédio de qualquer natureza? Se sim, demonstrar a medida em que as manifestações de apoio ao programa de integridade expressaram o compromisso com os temas. | E23: Sim, Não | F23: QN3 | G23: 5 | H23: Sim | J23: =IF(H23="Sim",G23, IF(H23="Parcialmente",G23/2, IF(OR(H23="Não",H23="Não se aplica"),0,""))) +IF(OR(H23="Sim",H23="Parcialmente"),Tabela1[[#This Row],[Pont. Resdist.]],0) | K23: Doc 12.4 - Email sobre assédio e canal de denúncias (26/03/2026) | L23: ATENDIDA (mantida da 1ª análise). Comunicação sobre assédio, discriminação e canal de denúncias enviada a toda a equipe (escritório e campo em grupos separados) em 26/03/2026, com cartilha institucional. Confirmada na reavaliação; a documentação complementar não a contradiz.
B24: I | C24: Questão | D24: 3.3 A pessoa jurídica destina recursos em seu orçamento para a manutenção das atividades relacionadas ao programa de integridade? Se sim, anexar documentos que comprovem a destinação de recursos para o programa de integridade. | E24: Sim, Não | F24: QN5 | G24: 18 | H24: Sim | J24: =IF(H24="Sim",G24, IF(H24="Parcialmente",G24/2, IF(OR(H24="Não",H24="Não se aplica"),0,""))) +IF(OR(H24="Sim",H24="Parcialmente"),Tabela1[[#This Row],[Pont. Resdist.]],0) | K24: Rel_Conformidade.pdf (Doc 12); Investig_Internas.pdf (Doc 12.6); Rel_Due_Diligence.pdf (Doc 12.7) | L24: ATENDIDA (mantida da 1ª análise). A empresa possui Oficial de Compliance (Yuri Renan) contratado e utiliza escritório de advocacia externo (Asseff Advogados) para conduções do Programa de Integridade, o que implica alocação de recursos financeiros. Contudo, não foi apresentado orçamento formal destinado ao PI. Como não há o quesito do julgamento parcial, opta-se pelo Sim. Confirmada na reavaliação; a documentação complementar não a contradiz.
B25: II | C25: Área | D25: Área II - Instância Interna Responsável pela Aplicação do Programa de Integridade
B26: II | C26: Grupo | D26: 4. Existência e estrutura da instância interna responsável pela aplicação do programa de integridade
B27: II | C27: Questão | D27: 4.1 A pessoa jurídica possui área ou pessoa responsável pela aplicação do programa de integridade? Se sim, anexar documentos que comprovem a existência da área específica ou pessoa responsável, informando a data em que a área foi instituída ou em que a pessoa responsável foi contratada/designada para a função e o currículo do atual responsável pelo programa de integridade. | E27: Sim, Não | F27: QN1 | G27: 20 | H27: Sim | J27: =IF(H27="Sim",G27, IF(H27="Parcialmente",G27/2, IF(OR(H27="Não",H27="Não se aplica"),0,""))) +IF(OR(H27="Sim",H27="Parcialmente"),Tabela1[[#This Row],[Pont. Resdist.]],0) | K27: Cód_Etica.pdf (Doc 12.1); Rel_Conformidade.pdf (Doc 12); Treinamento_Cód_Ética.pdf (Doc 12.2); Assédio.pdf (Doc 12.4) | L27: ATENDIDA (mantida da 1ª análise). QUESTÃO CRÍTICA ATENDIDA. A empresa possui Oficial de Compliance formalmente designado: Yuri Renan Procopio dos Santos Pinto Zolet (yuri.renan@jdseng.com.br). O profissional é mencionado no Código de Ética, no Relatório de Conformidade e nas comunicações internas, demonstrando atuação efetiva na função. Confirmada na reavaliação; a documentação complementar não a contradiz. Reforçada pela documentação complementar.
B28: II | C28: Questão | D28: 4.2 A instância interna responsável pelo programa de integridade está formalmente constituída, tendo suas atribuições expressamente previstas em documento aprovado pela alta direção da pessoa jurídica? Se sim, anexar documentos que comprovem a constituição formal da área responsável pelo programa de integridade, com suas atribuições e responsabilidades definidas. | E28: Sim, Não, Parcialmente | F28: QN2 | G28: 15 | H28: Sim | J28: =IF(H28="Sim",G28, IF(H28="Parcialmente",G28/2, IF(OR(H28="Não",H28="Não se aplica"),0,""))) +IF(OR(H28="Sim",H28="Parcialmente"),Tabela1[[#This Row],[Pont. Resdist.]],0) | K28: 1ª análise: Cód_Etica.pdf (Doc 12.1) Documentação complementar: Termo de Designação do Oficial de Compliance, 07/07/2026 | L28: ATENDIDA — superada com a documentação complementar. • Análise inicial (resposta anterior: Parcialmente): O Código de Ética menciona o Oficial de Compliance e suas atribuições gerais, mas não foi apresentado documento formal (resolução, portaria ou contrato) que constitua expressamente a instância, defina todas as suas atribuições e responsabilidades e registre a aprovação pela alta direção. • Complementação (nova documentação): O Termo de Designação do Oficial de Compliance (07/07/2026) assegura recursos, orçamento próprio e remuneração compatível, suprindo a parcialidade anterior.
B29: II | C29: Questão | D29: 4.3 A instância interna responsável pelo programa possui estrutura independente, não estando subordinada a outro departamento da pessoa jurídica – jurídico, auditoria, RH etc.? Se sim, anexar organograma que demonstre a estrutura atual da instância interna e suas linhas de reporte ou política/procedimento que formalize tal estrutura e linhas de reporte. | E29: Sim, Não, Não se aplica | F29: QN2 | G29: 15 | H29: Sim | J29: =IF(H29="Sim",G29, IF(H29="Parcialmente",G29/2, IF(OR(H29="Não",H29="Não se aplica"),0,""))) +IF(OR(H29="Sim",H29="Parcialmente"),Tabela1[[#This Row],[Pont. Resdist.]],0) | K29: 1ª análise: Doc 12.1, item 2.5; Doc 12, item 2.1 Documentação complementar: Termo de Designação do Oficial de Compliance, 07/07/2026 | L29: ATENDIDA — superada com a documentação complementar. • Análise inicial (resposta anterior: Não): O posicionamento hierárquico é mencionado no Código, mas sem documento formal que assegure independência e linha de reporte direto à alta direção. • Complementação (nova documentação): O Termo de Designação estabelece reporte direto à Diretoria, sem subordinação a outro departamento, conferindo independência à instância. | M29: Grupo: ESTRUTURA E ATIVIDADE ECONÔMICA Questão: Qual o porte da pessoa jurídica? Alternativa: Micro e Pequeno porte (de acordo com o Estatuto da Micro e Pequena pessoa jurídica) | N29: Distribuir 3,0 pontos para cada uma das questões (5): 4.1 4.2 4.4 5.1 5.2
B30: II | C30: Questão | D30: 4.4 A instância interna responsável pelo programa de integridade conta com quantitativo de funcionários proporcional às atribuições conferidas à área? Se sim, anexar documentos que demonstrem de forma expressa a estrutura de colaboradores alocados à área responsável pelo programa de integridade. | E30: Sim, Não | F30: QN5 | G30: 18 | H30: Sim | J30: =IF(H30="Sim",G30, IF(H30="Parcialmente",G30/2, IF(OR(H30="Não",H30="Não se aplica"),0,""))) +IF(OR(H30="Sim",H30="Parcialmente"),Tabela1[[#This Row],[Pont. Resdist.]],0) | K30: Doc 12.6; Doc 12.7 | L30: ATENDIDA (mantida da 1ª análise). O Oficial de Compliance conta com suporte da assessoria jurídica externa (Asseff Advogados) para investigações e due diligence, evidenciando acesso a recursos técnicos externos. Confirmada na reavaliação; a documentação complementar não a contradiz.
B31: II | C31: Grupo | D31: 5. Garantias atribuídas ao responsável pela instância interna para o exercício de suas atividades com autoridade e independência
B32: II | C32: Questão | D32: 5.1 O responsável pela instância interna de integridade possui garantias expressas que possibilitam o exercício das suas atribuições com independência e autoridade? Se sim, anexar documentos que comprovem a existência das garantias, a exemplo de mandato, nível de reporte, remuneração compatível com outras funções de mesmo nível hierárquico, livre acesso a documentos, pessoas e ativos da organização. | E32: Sim, Não, Parcialmente | F32: QN2 | G32: 15 | H32: Sim | J32: =IF(H32="Sim",G32, IF(H32="Parcialmente",G32/2, IF(OR(H32="Não",H32="Não se aplica"),0,""))) +IF(OR(H32="Sim",H32="Parcialmente"),Tabela1[[#This Row],[Pont. Resdist.]],0) | K32: 1ª análise: Cód_Etica.pdf (Doc 12.1) Documentação complementar: Termo de Designação do Oficial de Compliance, 07/07/2026 | L32: ATENDIDA — superada com a documentação complementar. • Análise inicial (resposta anterior: Não): Não foram apresentadas garantias expressas de independência e autoridade para o Oficial de Compliance, como mandato, nível de reporte formal à alta direção ou livre acesso documentado a sistemas e pessoas. O Código de Ética menciona a função mas não detalha as garantias. • Complementação (nova documentação): O Termo de Designação assegura garantias ao responsável: reporte direto, vedação de destituição/retaliação, livre acesso e participação em reuniões da Diretoria.
B33: II | C33: Questão | D33: 5.2 O responsável pela instância interna de integridade atua (diretamente ou como instância supervisora) na investigação e apuração de situações que configurem violações éticas ou legais? Se sim, anexar documentos que comprovem, no fluxo de tratamento de investigações e apurações de violações éticas e legais, que a instância interna atua diretamente ou mediante supervisão. | E33: Sim, Não | F33: QN4 | G33: 25 | H33: Sim | J33: =IF(H33="Sim",G33, IF(H33="Parcialmente",G33/2, IF(OR(H33="Não",H33="Não se aplica"),0,""))) +IF(OR(H33="Sim",H33="Parcialmente"),Tabela1[[#This Row],[Pont. Resdist.]],0) | K33: Doc 12.6; Doc 12.7; Doc 12.2; Doc 12.4 | L33: ATENDIDA (mantida da 1ª análise). O Oficial de Compliance participou diretamente: Investigação Interna 01/2024. Evidências de due diligence (09/2025), treinamento (08/2025) e comunicações sobre assédio (03/2026) não são aqui consideradas. Confirmada na reavaliação; a documentação complementar não a contradiz.
B34: III | C34: Área | D34: Área III - Gestão de Riscos para Integridade
B35: III | C35: Grupo | D35: 6. Gestão de riscos para integridade
B36: III | C36: Questão | D36: 6.1 Existe na pessoa jurídica política ou planejamento que trate da gestão de riscos e que defina a metodologia para a realização da análise de riscos? Se sim, anexar a política, metodologia ou outros documentos que formalizam a atividade de gestão de riscos. | E36: Sim, Não, Parcialmente | F36: QN2 | G36: 15 | H36: Sim | J36: =IF(H36="Sim",G36, IF(H36="Parcialmente",G36/2, IF(OR(H36="Não",H36="Não se aplica"),0,""))) +IF(OR(H36="Sim",H36="Parcialmente"),Tabela1[[#This Row],[Pont. Resdist.]],0) | K36: 1ª análise: Rel_Conformidade.pdf (Doc 12) — menciona gestão de riscos sem documentar a metodologia Documentação complementar: Matriz de Riscos de Integridade V.01/V.02.2026 (Termo de Aprovação da Diretoria, 24/03 e 30/07/2026) | L36: ATENDIDA — superada com a documentação complementar. • Análise inicial (resposta anterior: Não): Não foi apresentada política ou metodologia formal de gestão de riscos de integridade. O Relatório de Conformidade menciona a gestão de riscos como componente do programa, mas nenhum documento específico de política ou metodologia de análise de riscos foi juntado ao dossiê. • Complementação (nova documentação): A Matriz de Riscos de Integridade e seu Termo de Aprovação estabelecem metodologia, critérios de revisão e responsáveis, configurando planejamento formal de gestão de riscos.
B37: III | C37: Agrupadora | D37: 6.2 A política ou planejamento que trata da gestão de riscos:
B38: III | C38: Questão | D38: 6.2.1 institui a periodicidade mínima para atualização/revisão do processo de análise de riscos? Se sim, informar o item ou página da política, metodologia ou outro documento que comprove a existência do requisito. | E38: Sim, Não | F38: QN3 | G38: 5 | H38: Sim | J38: =IF(H38="Sim",G38, IF(H38="Parcialmente",G38/2, IF(OR(H38="Não",H38="Não se aplica"),0,""))) +IF(OR(H38="Sim",H38="Parcialmente"),Tabela1[[#This Row],[Pont. Resdist.]],0) | K38: 1ª análise: (sem documento) Documentação complementar: Matriz de Riscos de Integridade V.01/V.02.2026 (Termo de Aprovação da Diretoria, 24/03 e 30/07/2026) | L38: ATENDIDA — superada com a documentação complementar. • Análise inicial (resposta anterior: Não): Sem política formal de gestão de riscos, este quesito não é atendido. • Complementação (nova documentação): O Termo de Aprovação define revisão anual (ou por fato relevante), com próxima revisão ordinária em março/2027.
B39: III | C39: Questão | D39: 6.2.2 determina a área ou pessoa responsável pela gestão de riscos? Se sim, informar o item ou página da política, metodologia ou outro documento que comprove a existência do requisito. | E39: Sim, Não | F39: QN3 | G39: 5 | H39: Sim | J39: =IF(H39="Sim",G39, IF(H39="Parcialmente",G39/2, IF(OR(H39="Não",H39="Não se aplica"),0,""))) +IF(OR(H39="Sim",H39="Parcialmente"),Tabela1[[#This Row],[Pont. Resdist.]],0) | K39: 1ª análise: (sem documento) Documentação complementar: Matriz de Riscos de Integridade V.01/V.02.2026 (Termo de Aprovação da Diretoria, 24/03 e 30/07/2026); Termo de Designação do Oficial de Compliance, 07/07/2026 | L39: ATENDIDA — superada com a documentação complementar. • Análise inicial (resposta anterior: Não): Sem política formal de gestão de riscos, este quesito não é atendido. • Complementação (nova documentação): A gestão de riscos é atribuída ao Oficial de Compliance, com responsáveis por risco definidos na Matriz.
B40: III | C40: Questão | D40: 6.2.3 inclui sua revisão e aprovação pela alta direção? Se sim, informar o item ou página da política, metodologia ou outro documento que comprove a existência do requisito. | E40: Sim, Não | F40: QN3 | G40: 5 | H40: Sim | J40: =IF(H40="Sim",G40, IF(H40="Parcialmente",G40/2, IF(OR(H40="Não",H40="Não se aplica"),0,""))) +IF(OR(H40="Sim",H40="Parcialmente"),Tabela1[[#This Row],[Pont. Resdist.]],0) | K40: 1ª análise: (sem documento) Documentação complementar: Matriz de Riscos de Integridade V.01/V.02.2026 (Termo de Aprovação da Diretoria, 24/03 e 30/07/2026) | L40: ATENDIDA — superada com a documentação complementar. • Análise inicial (resposta anterior: Não): Sem política formal de gestão de riscos, este quesito não é atendido. • Complementação (nova documentação): A Matriz foi revisada e aprovada formalmente pela Diretoria Executiva (24/03/2026 e 30/07/2026).
B41: III | C41: Questão | D41: 6.3 A pessoa jurídica realizou, nos últimos 24 meses, uma análise de riscos que contempla expressamente riscos para integridade, isto é, aqueles relacionados a corrupção e fraude? Se sim, anexar a matriz de riscos ou documento equivalente, incluindo comprovação de que foi aprovado pela alta direção da entidade, no período indicado. | E41: Sim, Não | F41: QN1 | G41: 20 | H41: Sim | J41: =IF(H41="Sim",G41, IF(H41="Parcialmente",G41/2, IF(OR(H41="Não",H41="Não se aplica"),0,""))) +IF(OR(H41="Sim",H41="Parcialmente"),Tabela1[[#This Row],[Pont. Resdist.]],0) | K41: 1ª análise: Relatorio_Perfil.pdf (Doc 10, PGR-NR1, STARMED, 10/07/2025, folhas 132-141) — riscos OCUPACIONAIS apenas. Ausência de matriz de riscos de integridade/compliance. Documentação complementar: Matriz de Riscos de Integridade V.01/V.02.2026 (Termo de Aprovação da Diretoria, 24/03 e 30/07/2026) | L41: ATENDIDA — superada com a documentação complementar. • Análise inicial (resposta anterior: Não): QUESTÃO CRÍTICA — RESULTADO ELIMINATÓRIO. Não foi apresentada análise de riscos de INTEGRIDADE (corrupção e fraude). O Doc 10 (Relatorio_Perfil.pdf) contém um PGR - Programa de Gerenciamento de Riscos Ocupacionais (NR-1), elaborado pela STARMED em 10/07/2025, com matriz de riscos e inventário por GHE (riscos físicos, químicos, ergonômicos e de acidente de trabalho). Contudo, este é um documento de saúde e segurança ocupacional, obrigatório pela NR-1 do Ministério do Trabalho, que NÃO se confunde com a análise de riscos para integridade exigida pelo Decreto 12.304/2024 e pela Portaria SE/CGU nº 226/2025. A Portaria exige expressamente mapeamento de riscos 'relacionados a corrupção e fraude' — dimensão completamente ausente no PGR. A questão configura hipótese de indeferimento automático. • Complementação (nova documentação): A Matriz de Riscos de Integridade contempla expressamente riscos de corrupção e fraude, abrangendo TI, Financeiro, Projetos, Operações e Licitações, aprovada pela alta direção no período. Supre a lacuna eliminatória.
B42: III | C42: Questão | D42: 6.3.1 A análise de riscos contempla o mapeamento dos riscos para integridade relacionados à sua participação em licitações e na execução de contratos administrativos? Se sim, anexar a matriz de riscos ou documento equivalente que contenha os riscos mapeados relacionados à participação da entidade em licitações e contratos administrativos. | E42: Sim, Não | F42: QN3 | G42: 5 | H42: Sim | J42: =IF(H42="Sim",G42, IF(H42="Parcialmente",G42/2, IF(OR(H42="Não",H42="Não se aplica"),0,""))) +IF(OR(H42="Sim",H42="Parcialmente"),Tabela1[[#This Row],[Pont. Resdist.]],0) | K42: 1ª análise: (sem documento) Documentação complementar: Matriz de Riscos de Integridade V.01/V.02.2026 (Termo de Aprovação da Diretoria, 24/03 e 30/07/2026) | L42: ATENDIDA — superada com a documentação complementar. • Análise inicial (resposta anterior: Não): Ausência de matriz de riscos que contemple especificamente os riscos relacionados à participação em licitações e execução de contratos administrativos. • Complementação (nova documentação): A Matriz mapeia os riscos de integridade por área/subprocesso, com evento, causa e consequência. | O42: Bom ponto para citar no Relatório Final
...

Sheet Contadores
B1: DADOS REFERENTES AO FORMULÁRIO DE CONFORMIDADE
B3: Áreas | C3: I | D3: II | E3: III | F3: IV | G3: V | H3: VI | I3: VII | J3: VIII | K3: IX | L3: X | M3: XI | N3: TOTAL | O3: XII | R3: Tipo | S3: Val Unit. | T3: Qtde Itens | U3: % total | V3: Pontos
B4: Grupos | C4: =COUNTIFS('Formulário de Conformidade'!$C:$C,"Grupo",'Formulário de Conformidade'!$B:$B,C3) | D4: =COUNTIFS('Formulário de Conformidade'!$C:$C,"Grupo",'Formulário de Conformidade'!$B:$B,D3) | E4: =COUNTIFS('Formulário de Conformidade'!$C:$C,"Grupo",'Formulário de Conformidade'!$B:$B,E3) | F4: =COUNTIFS('Formulário de Conformidade'!$C:$C,"Grupo",'Formulário de Conformidade'!$B:$B,F3) | G4: =COUNTIFS('Formulário de Conformidade'!$C:$C,"Grupo",'Formulário de Conformidade'!$B:$B,G3) | H4: =COUNTIFS('Formulário de Conformidade'!$C:$C,"Grupo",'Formulário de Conformidade'!$B:$B,H3) | I4: =COUNTIFS('Formulário de Conformidade'!$C:$C,"Grupo",'Formulário de Conformidade'!$B:$B,I3) | J4: =COUNTIFS('Formulário de Conformidade'!$C:$C,"Grupo",'Formulário de Conformidade'!$B:$B,J3) | ... M4: =COUNTIFS('Formulário de Conformidade'!$C:$C,"Grupo",'Formulário de Conformidade'!$B:$B,M3) | N4: =SUM(C4:M4) | O4: =COUNTIFS('Formulário de Conformidade'!$C:$C,"Grupo",'Formulário de Conformidade'!$B:$B,O3) | R4: QN1 | S4: 20 | T4: =COUNTIF('Formulário de Conformidade'!F1:F160, R4) | U4: =T4/N5 | V4: =S4*T4
B5: Questões | C5: =COUNTIFS('Formulário de Conformidade'!$C:$C,"Questão",'Formulário de Conformidade'!$B:$B,C3) | D5: =COUNTIFS('Formulário de Conformidade'!$C:$C,"Questão",'Formulário de Conformidade'!$B:$B,D3) | E5: =COUNTIFS('Formulário de Conformidade'!$C:$C,"Questão",'Formulário de Conformidade'!$B:$B,E3) | F5: =COUNTIFS('Formulário de Conformidade'!$C:$C,"Questão",'Formulário de Conformidade'!$B:$B,F3) | G5: =COUNTIFS('Formulário de Conformidade'!$C:$C,"Questão",'Formulário de Conformidade'!$B:$B,G3) | H5: =COUNTIFS('Formulário de Conformidade'!$C:$C,"Questão",'Formulário de Conformidade'!$B:$B,H3) | I5: =COUNTIFS('Formulário de Conformidade'!$C:$C,"Questão",'Formulário de Conformidade'!$B:$B,I3) | J5: =COUNTIFS('Formulário de Conformidade'!$C:$C,"Questão",'Formulário de Conformidade'!$B:$B,J3) | ... M5: =COUNTIFS('Formulário de Conformidade'!$C:$C,"Questão",'Formulário de Conformidade'!$B:$B,M3) | N5: =SUM(C5:M5) | O5: =COUNTIFS('Formulário de Conformidade'!$C:$C,"Questão",'Formulário de Conformidade'!$B:$B,O3) | R5: QN2 | S5: 15 | T5: =COUNTIF('Formulário de Conformidade'!F1:F160, R5) | U5: =T5/$N5 | V5: =S5*T5
B6: Pontuação | C6: =SUMIFS('Formulário de Conformidade'!$G:$G,'Formulário de Conformidade'!$C:$C,"Questão",'Formulário de Conformidade'!$B:$B,C3) | D6: =SUMIFS('Formulário de Conformidade'!$G:$G,'Formulário de Conformidade'!$C:$C,"Questão",'Formulário de Conformidade'!$B:$B,D3) | E6: =SUMIFS('Formulário de Conformidade'!$G:$G,'Formulário de Conformidade'!$C:$C,"Questão",'Formulário de Conformidade'!$B:$B,E3) | F6: =SUMIFS('Formulário de Conformidade'!$G:$G,'Formulário de Conformidade'!$C:$C,"Questão",'Formulário de Conformidade'!$B:$B,F3) | G6: =SUMIFS('Formulário de Conformidade'!$G:$G,'Formulário de Conformidade'!$C:$C,"Questão",'Formulário de Conformidade'!$B:$B,G3) | H6: =SUMIFS('Formulário de Conformidade'!$G:$G,'Formulário de Conformidade'!$C:$C,"Questão",'Formulário de Conformidade'!$B:$B,H3) | I6: =SUMIFS('Formulário de Conformidade'!$G:$G,'Formulário de Conformidade'!$C:$C,"Questão",'Formulário de Conformidade'!$B:$B,I3) | J6: =SUMIFS('Formulário de Conformidade'!$G:$G,'Formulário de Conformidade'!$C:$C,"Questão",'Formulário de Conformidade'!$B:$B,J3) | ... M6: =SUMIFS('Formulário de Conformidade'!$G:$G,'Formulário de Conformidade'!$C:$C,"Questão",'Formulário de Conformidade'!$B:$B,M3) | N6: =SUM(C6:M6) | O6: =SUMIFS('Formulário de Conformidade'!$G:$G,'Formulário de Conformidade'!$C:$C,"Questão",'Formulário de Conformidade'!$B:$B,O3) | R6: QN3 | S6: 5 | T6: =COUNTIF('Formulário de Conformidade'!F1:F160, R6) | U6: =T6/$N5 | V6: =S6*T6
B7: % Pontuação Metodologia | C7: =C6/$N6 | D7: =D6/$N6 | E7: =E6/$N6 | F7: =F6/$N6 | G7: =G6/$N6 | H7: =H6/$N6 | I7: =I6/$N6 | J7: =J6/$N6 | ... M7: =M6/$N6 | N7: =SUM(C7:M7) | O7: =O6/$N6 | R7: QN4 | S7: 25 | T7: =COUNTIF('Formulário de Conformidade'!F1:F160, R7) | U7: =T7/$N5 | V7: =S7*T7
B8: % Pró-Ética | C8: 0.13 | D8: 0.13 | E8: 0.1 | F8: 0.05 | G8: 0.13 | H8: 0.11 | I8: 0.06 | J8: 0.09 | K8: 0.1 | L8: 0.05 | M8: 0.05 | N8: =SUM(C8:M8) | O8: - | R8: QN5 | S8: 18 | T8: =COUNTIF('Formulário de Conformidade'!F1:F160, R8) | U8: =T8/$N5 | V8: =S8*T8

Sheet Resultado
B3: Áreas Avaliadas | C3: Pontuação máxima | D3: Percentual mínimo | E3: Pontuação Atingida | F3: Percentual Antingido | G3: Questões QN1 | H3: Questões QN4
B4: Área I - Comprometimento da Alta Direção da Pessoa jurídica | C4: 154 | D4: 0.3 | E4: =SUM('Formulário de Conformidade'!J11:J24) | F4: =E4/C4
B5: Área II - Instância Interna Responsável pela Aplicação do Programa de Integridade | C5: 108 | D5: 0.3 | E5: =SUM('Formulário de Conformidade'!J27:J33) | F5: =E5/C5
B6: Área III - Gestão de Riscos para Integridade | C6: 78 | D6: 0.3 | E6: =SUM('Formulário de Conformidade'!J36:J44) | F6: =E6/C6
B7: Área IV - Código de Ética e Conduta | C7: 91 | D7: 0.3 | E7: =SUM('Formulário de Conformidade'!J47:J57) | F7: =E7/C7
B8: Área V - Políticas e Procedimentos de Integridade e de Prevenção de Ilícitos em Licitações e Contratos Administrativos | C8: 130 | D8: 0.3 | E8: =SUM('Formulário de Conformidade'!J61:J74) | F8: =E8/C8
B9: Área VI - Treinamentos e Ações de Comunicação sobre o Programa de Integridade | C9: 118 | D9: 0.3 | E9: =SUM('Formulário de Conformidade'!J77:J84) | F9: =E9/C9
B10: Área VII - Controles Contábeis, Financeiros e Auditoria Interna | C10: 106 | D10: 0.3 | E10: =SUM('Formulário de Conformidade'!J87:J96) | F10: =E10/C10
B11: Área VIII - Diligências para Contratação e Supervisão de Terceiros e para Fusões e Aquisições Societárias | C11: 114 | D11: 0.3 | E11: =SUM('Formulário de Conformidade'!J99:J112) | F11: =E11/C11
B12: Área IX - Canais de Denúncia, Remediação e Medidas Disciplinares | C12: 141 | D12: 0.3 | E12: =SUM('Formulário de Conformidade'!J115:J133) | F12: =E12/C12
B13: Área X - Monitoramento do Programa de Integridade | C13: 83 | D13: 0.3 | E13: =SUM('Formulário de Conformidade'!J136:J144) | F13: =E13/C13
B14: Área XI - Responsabilidade Socioambiental e Transparência | C14: 83 | D14: 0.3 | E14: =SUM('Formulário de Conformidade'!J147:J160) | F14: =E14/C14
B15: Área XII - Medidas de Remediação adotadas em face dos atos que ensejaram a aplicação da sanção | C15: 95 | D15: 0.7 | E15: =SUM('Formulário de Conformidade'!J163:J173) | F15: =E15/C15
B16: TOTAL | C16: =SUM(C4:C15) | D16: 0.45 | E16: =SUM(E4:E15) | F16: =E16/C16

Sheet Planilha2

Sheet 3  Validação da Tabela Pergunta
A1: DescTituloPerguntaFormularioTipoAvaliacao | B1: IdBlocoFormularioTipoAvaliacao | C1: FlgAgrupadora | D1: FlgDistribuicaoValorRespostaNaoSeAplica | E1: FlgRespostaPossivelNaoSeAplica | F1: FlgRespostaPossivelParcialmente | G1: FlgRespostaPossivelSimNao | H1: FlgSolicitantePodeResponder | I1: NumOrdem | J1: ValFixoPontuacaoItem | K1: FlgEvidenciaObrigatoria | L1: FlgMedidaMinimaAdocaoProgramaIntegridade | M1: FlgObservacaoObrigatoria | N1: TxtInformacaoAdicional
A2: 1.1 A pessoa jurídica possui critérios de integridade formalizados para seleção dos candidatos aos cargos da alta direção? Se sim, anexar documentos que comprovem a existência dos critérios de integridade para seleção e informar os cargos a que são aplicados, a forma como os critérios são considerados e os responsáveis por sua avaliação. | B2: 293 | C2: FALSE | D2: FALSE | E2: FALSE | F2: FALSE | G2: TRUE | H2: TRUE | I2: 1 | J2: 15 | K2: TRUE | L2: FALSE | M2: FALSE | N2: Evidências que comprovem que a pessoa jurídica possui critérios éticos, como políticas de seleção e procedimentos de contratação, para escolha de membros da alta direção.
A3: 1.2 A pessoa jurídica aplicou critérios de integridade para seleção dos ocupantes de cargos da alta direção contratados nos últimos 24 meses? Se sim, anexar documentos que comprovem a aplicação dos critérios de integridade para seleção. | B3: 293 | C3: FALSE | D3: TRUE | E3: TRUE | F3: FALSE | G3: TRUE | H3: TRUE | I3: 2 | J3: 18 | K3: TRUE | L3: FALSE | M3: FALSE | N3: Evidências que comprovem a aplicação de critérios de integridade na escolha da alta direção, incluindo testes de integridade, background check, Know Your Employee - KYE, pesquisas em fontes abertas e análises de antecedentes sobre histórico profissional, práticas ilícitas e conduta ética.
A4: 1.3 A pessoa jurídica possui política de remuneração variável para os membros da alta direção condicionada ao atingimento de metas de desempenho relacionadas aos indicadores de aplicação ao programa de integridade? Se sim, anexar a política de remuneração que comprova a existência dessa regra e descrever como ela é aplicada. | B4: 293 | C4: FALSE | D4: TRUE | E4: TRUE | F4: FALSE | G4: TRUE | H4: TRUE | I4: 3 | J4: 15 | K4: TRUE | L4: FALSE | M4: FALSE | N4: Evidências da adoção de norma formal que vincula a remuneração variável da alta direção ao cumprimento de metas relacionadas aos indicadores do programa de integridade.
A5: 2.1 A aprovação das principais políticas relacionadas ao programa de integridade é feita pelas mais elevadas instâncias decisórias da pessoa jurídica? Se sim, anexar documentos que comprovem a aprovação das principais políticas relacionadas ao programa de integridade pela alta direção. | B5: 294 | C5: FALSE | D5: FALSE | E5: FALSE | F5: FALSE | G5: TRUE | H5: TRUE | I5: 1 | J5: 20 | K5: TRUE | L5: TRUE | M5: FALSE | N5: Evidências da participação da alta direção na aprovação de políticas do programa de integridade, como atas de reuniões, e-mails ou documentos que comprovem a criação ou atualização de políticas, estruturas e procedimentos, ou registros incluídos na própria política.
A6: 2.2 A pessoa jurídica possui em sua estrutura de governança órgão colegiado (como comitê ou conselho de ética) para deliberar sobre temas de ética e integridade, que contam com a participação de membros da alta direção? Se sim, anexar documentos que comprovem a existência do órgão colegiado e a participação dos membros da alta direção em sua composição. | B6: 294 | C6: FALSE | D6: TRUE | E6: TRUE | F6: FALSE | G6: TRUE | H6: TRUE | I6: 2 | J6: 15 | K6: TRUE | L6: FALSE | M6: FALSE | N6: Evidências da existência de um órgão colegiado responsável por tratar de temas do programa de integridade, como estatutos, regimentos, políticas internas e atas, demonstrando a participação ativa dos membros da alta direção nesse colegiado.
A7: 2.3 A alta direção da pessoa jurídica supervisiona, diretamente ou por intermédio de órgão colegiado do qual ela participe, a implantação e a aplicação do programa de integridade, por meio do recebimento e avaliação de relatórios periódicos de acompanhamento das atividades relacionadas ao programa de integridade? | B7: 294 | C7: FALSE | D7: FALSE | E7: FALSE | F7: TRUE | G7: TRUE | H7: TRUE | I7: 3 | J7: 18 | K7: TRUE | L7: FALSE | M7: FALSE | N7: Evidências que comprovem a supervisão da alta direção na implantação e aplicação do programa de integridade, como atas de reuniões, e-mails, apresentações feitas em reuniões, registros de frequência das ações de supervisão, relatórios assinados e documentos que demonstrem o acompanhamento das atividades do programa.
A8: 3.1 Os membros da alta direção, individualmente, manifestam publicamente apoio ao programa de integridade? Se sim, anexar documentos e/ou indicar, no campo correspondente, link em que seja possível visualizar as manifestações de apoio ao programa de integridade por membros da alta direção. | B8: 295 | C8: FALSE | D8: FALSE | E8: FALSE | F8: FALSE | G8: TRUE | H8: TRUE | I8: 1 | J8: 20 | K8: TRUE | L8: FALSE | M8: FALSE | N8: Evidências de que a alta direção, de forma individualizada, reforça seu compromisso com a ética e a integridade, por meio de comunicados estratégicos em canais como e-mails, redes sociais, intranet, vídeos institucionais e comunicados internos e externos, demonstrando apoio ao programa de integridade.
A9: 3.2 As manifestações de apoio ao programa de integridade por membros da alta direção: | B9: 295 | C9: TRUE | D9: FALSE | E9: FALSE | F9: FALSE | G9: FALSE | H9: TRUE | I9: 2 | J9: 0 | K9: FALSE | L9: FALSE | M9: FALSE
A10: 3.2.1 são feitas de forma periódica e divulgadas por diferentes meios para alcançar o público interno e externo da pessoa jurídica em toda sua diversidade? Se sim, demonstrar a medida em que as manifestações de apoio ao programa de integridade ocorreram de forma periódica e direcionadas aos diferentes públicos da entidade. | B10: 295 | C10: FALSE | D10: FALSE | E10: FALSE | F10: TRUE | G10: TRUE | H10: TRUE | I10: 3 | J10: 5 | K10: TRUE | L10: FALSE | M10: FALSE | N10: Evidências de que as declarações de apoio ao programa de integridade foram feitas por diferentes membros da alta direção e de forma periódica, reforçando o compromisso da liderança com a ética e a transparência.
A11: 3.2.2 expressam uma mensagem de incentivo à adoção de uma conduta ética, seguindo os ditames do programa de integridade? Se sim, demonstrar a medida em que as manifestações de apoio ao programa de integridade expressaram o compromisso com os temas. | B11: 295 | C11: FALSE | D11: FALSE | E11: FALSE | F11: FALSE | G11: TRUE | H11: TRUE | I11: 4 | J11: 5 | K11: TRUE | L11: FALSE | M11: FALSE | N11: Evidências de mensagens claras da alta direção aos colaboradores, sociedade, mercado e stakeholders, reforçando o compromisso da pessoa jurídica no combate ao preconceito, discriminação e assédio em qualquer forma.
A12: 3.2.3 expressam o compromisso da alta direção com o combate ao preconceito, à discriminação e ao assédio de qualquer natureza? Se sim, demonstrar a medida em que as manifestações de apoio ao programa de integridade expressaram o compromisso com os temas. | B12: 295 | C12: FALSE | D12: FALSE | E12: FALSE | F12: FALSE | G12: TRUE | H12: TRUE | I12: 5 | J12: 5 | K12: TRUE | L12: FALSE | M12: FALSE | N12: Evidências de mensagens claras da alta direção aos colaboradores, sociedade, mercado e stakeholders, reforçando o compromisso da pessoa jurídica no combate ao preconceito, discriminação e assédio em qualquer forma.
A13: 3.3 A pessoa jurídica destina recursos em seu orçamento para a manutenção das atividades relacionadas ao programa de integridade? Se sim, anexar documentos que comprovem a destinação de recursos para o programa de integridade. | B13: 295 | C13: FALSE | D13: FALSE | E13: FALSE | F13: FALSE | G13: TRUE | H13: TRUE | I13: 6 | J13: 18 | K13: TRUE | L13: FALSE | M13: FALSE | N13: Evidências que comprovem a elaboração de orçamento que destine recursos específicos para a área responsável pelo programa de integridade, antes de cada exercício, tais como: orçamento, atas de reunião com aprovação orçamentária etc., que contemplem as despesas programadas para a área.
A14: 4.1 A pessoa jurídica possui área ou pessoa responsável pela aplicação do programa de integridade? Se sim, anexar documentos que comprovem a existência da área específica ou pessoa responsável, informando a data em que a área foi instituída ou em que a pessoa responsável foi contratada/designada para a função e o currículo do atual responsável pelo programa de integridade. | B14: 297 | C14: FALSE | D14: FALSE | E14: FALSE | F14: FALSE | G14: TRUE | H14: TRUE | I14: 1 | J14: 20 | K14: TRUE | L14: TRUE | M14: FALSE | N14: Evidências sobre a existência de uma instância interna (seja uma área ou pessoa designada) responsável pela implementação, fiscalização e monitoramento contínuo do programa de integridade no Brasil, tais como: políticas, regimento interno, estatuto, job description etc. Não serão considerados órgãos colegiados (comitês, conselhos etc).
A15: 4.2 A instância interna responsável pelo programa de integridade está formalmente constituída, tendo suas atribuições expressamente previstas em documento aprovado pela alta direção da pessoa jurídica? Se sim, anexar documentos que comprovem a constituição formal da área responsável pelo programa de integridade, com suas atribuições e responsabilidades definidas. | B15: 297 | C15: FALSE | D15: FALSE | E15: FALSE | F15: TRUE | G15: TRUE | H15: TRUE | I15: 2 | J15: 15 | K15: FALSE | L15: FALSE | M15: FALSE | N15: Evidências documentais que descrevam explicitamente a área responsável pelo programa de integridade, com suas atribuições e responsabilidades detalhadas, tais como regimentos internos, estatuto social, regimentos, políticas e atas de reuniões que comprovem a criação, estrutura e funcionamento do setor, aprovado pela alta direção.
A16: 4.3 A instância interna responsável pelo programa possui estrutura independente, não estando subordinada a outro departamento da pessoa jurídica – jurídico, auditoria, RH etc.? Se sim, anexar organograma que demonstre a estrutura atual da instância interna e suas linhas de reporte ou política/procedimento que formalize tal estrutura e linhas de reporte. | B16: 297 | C16: FALSE | D16: TRUE | E16: TRUE | F16: FALSE | G16: TRUE | H16: TRUE | I16: 3 | J16: 15 | K16: TRUE | L16: FALSE | M16: FALSE | N16: Evidência como política ou procedimento que formalize tal estrutura, organograma da pessoa jurídica que demonstre a posição hierárquica e as linhas de reporte da área de integridade.
A17: 4.4 A instância interna responsável pelo programa de integridade conta com quantitativo de funcionários proporcional às atribuições conferidas à área? Se sim, anexar documentos que demonstrem de forma expressa a estrutura de colaboradores alocados à área responsável pelo programa de integridade. | B17: 297 | C17: FALSE | D17: FALSE | E17: FALSE | F17: FALSE | G17: TRUE | H17: TRUE | I17: 4 | J17: 18 | K17: TRUE | L17: FALSE | M17: FALSE | N17: Evidências que demonstrem o quantitativo de funcionários alocados na área de integridade, exclusiva ou parcialmente, correlacionando essa estrutura às atribuições previstas para a instância responsável pelo programa de integridade.
A18: 5.1 O responsável pela instância interna de integridade possui garantias expressas que possibilitam o exercício das suas atribuições com independência e autoridade? Se sim, anexar documentos que comprovem a existência das garantias, a exemplo de mandato, nível de reporte, remuneração compatível com outras funções de mesmo nível hierárquico, livre acesso a documentos, pessoas e ativos da organização. | B18: 296 | C18: FALSE | D18: FALSE | E18: FALSE | F18: TRUE | G18: TRUE | H18: TRUE | I18: 1 | J18: 15 | K18: TRUE | L18: FALSE | M18: FALSE | N18: Evidências como estatuto, política de integridade ou job description, que definem garantias da área responsável pelo programa de integridade, incluindo independência, acesso a informações, proteção contra punições arbitrárias e validade de decisões.
A19: 5.2 O responsável pela instância interna de integridade atua (diretamente ou como instância supervisora) na investigação e apuração de situações que configurem violações éticas ou legais? Se sim, anexar documentos que comprovem, no fluxo de tratamento de investigações e apurações de violações éticas e legais, que a instância interna atua diretamente ou mediante supervisão. | B19: 296 | C19: FALSE | D19: FALSE | E19: FALSE | F19: FALSE | G19: TRUE | H19: TRUE | I19: 2 | J19: 25 | K19: TRUE | L19: FALSE | M19: FALSE | N19: Evidências como estatuto, política de integridade ou job description, que estabelecem a atuação direta ou supervisão da instância de integridade no fluxo de investigações e apurações.
