Workbook
Name Grande: #REF!

Sheet Menu
E4: Mapeamento de Risco de Compliance

Sheet Compliance
F6: Análise de Risco
B7: Ref. | C7: Processo | D7: Risco | E7: Recomendação | F7: Impacto | G7: Classificação do Risco | H7: Probabilidade | I7: Cálculo | J7: Análise de Risco
B8: R.COM.01 | C8: Compliance | D8: Risco de transgressão dos controles internos de compliance por funcionários ou terceiros da DECAL Brasil. | E8: Recomendamos que seja realizado um monitoramento dos controles e riscos de compliance, para garantir a efetividade do programa de integridade da DECAL Brasil. O monitoramento deve garantir que todos os procedimentos definidos nas políticas relacionadas ao programa de integridade estão sendo seguidos. | F8: 5 - Muito Alto | G8: Fraude e Corrupção | H8: 3 - Possível | I8: =(IF(F8="1 - Muito Baixo",1,IF(F8="2 - Baixo",2,IF(F8="3 - Médio",3,IF(F8="4 - Alto",4,IF(F8="5 - Muito Alto",5,0))))))*(IF(H8="1 - Raramente",1,IF(H8="2 - Pouco Provável",2,IF(H8="3 - Possível",3,IF(H8="4 - Muito provável",4,IF(H8="5 - Quase Certa ocorrência",5,0)))))) -> 15 | J8: =IF(I8=1,"Baixo (1)",IF(I8=2,"Baixo (2)",IF(I8=3,"Baixo (3)",IF(I8=4,"Baixo (4)",IF(I8=5,"Médio (5)",IF(I8=6,"Médio (6)",IF(I8=8,"Médio (8)",IF(I8=9,"Médio (9)",IF(I8=10,"Alto (10)",IF(I8=12,"Alto (12)",IF(I8=15,"Alto (15)",IF(I8=16,"Alto (16)",IF(I8=20,"Muito Alto (20)",IF(I8=25,"Muito Alto (25)","Erro")))))))))))))) -> Alto (15)
B9: R.COM.02 | C9: Compliance | D9: Risco de ausência de denúncias/comunicação de funcionários em caso descumprimento das regras de compliance cometidos por membros da DECAL Brasil ou em nome da empresa. | E9: Recomendamos que os canais de denúncias da DECAL Brasil sejam amplamente divulgados através de informativos, intranet, banner e treinamento, reiterando para todos os funcionários as prerrogativas de sigilo, confidencialidade e segurança na realização de denúncias. | F9: 5 - Muito Alto | G9: Fraude | H9: 3 - Possível | I9: =(IF(F9="1 - Muito Baixo",1,IF(F9="2 - Baixo",2,IF(F9="3 - Médio",3,IF(F9="4 - Alto",4,IF(F9="5 - Muito Alto",5,0))))))*(IF(H9="1 - Raramente",1,IF(H9="2 - Pouco Provável",2,IF(H9="3 - Possível",3,IF(H9="4 - Muito provável",4,IF(H9="5 - Quase Certa ocorrência",5,0)))))) -> 15 | J9: =IF(I9=1,"Baixo (1)",IF(I9=2,"Baixo (2)",IF(I9=3,"Baixo (3)",IF(I9=4,"Baixo (4)",IF(I9=5,"Médio (5)",IF(I9=6,"Médio (6)",IF(I9=8,"Médio (8)",IF(I9=9,"Médio (9)",IF(I9=10,"Alto (10)",IF(I9=12,"Alto (12)",IF(I9=15,"Alto (15)",IF(I9=16,"Alto (16)",IF(I9=20,"Muito Alto (20)",IF(I9=25,"Muito Alto (25)","Erro")))))))))))))) -> Alto (15)
B10: R.COM.03 | C10: Compliance | D10: Risco de ausência de monitoramento e tratamento das denúncias realizadas através dos canais de denúncias. | E10: Recomendamos que todas as denúncias sejam previamente avaliadas e classificadas quanto ao impacto (baixo, médio ou alto) e exposição (baixa, média ou alta) da DECAL Brasil e, para cada uma das classificações, prazos máximos para tratamento e conclusão sejam definidos. | F10: 5 - Muito Alto | G10: Fraude | H10: 3 - Possível | I10: =(IF(F10="1 - Muito Baixo",1,IF(F10="2 - Baixo",2,IF(F10="3 - Médio",3,IF(F10="4 - Alto",4,IF(F10="5 - Muito Alto",5,0))))))*(IF(H10="1 - Raramente",1,IF(H10="2 - Pouco Provável",2,IF(H10="3 - Possível",3,IF(H10="4 - Muito provável",4,IF(H10="5 - Quase Certa ocorrência",5,0)))))) -> 15 | J10: =IF(I10=1,"Baixo (1)",IF(I10=2,"Baixo (2)",IF(I10=3,"Baixo (3)",IF(I10=4,"Baixo (4)",IF(I10=5,"Médio (5)",IF(I10=6,"Médio (6)",IF(I10=8,"Médio (8)",IF(I10=9,"Médio (9)",IF(I10=10,"Alto (10)",IF(I10=12,"Alto (12)",IF(I10=15,"Alto (15)",IF(I10=16,"Alto (16)",IF(I10=20,"Muito Alto (20)",IF(I10=25,"Muito Alto (25)","Erro")))))))))))))) -> Alto (15)
B11: R.COM.04 | C11: Compliance | D11: Risco de desconhecimento dos funcionários da DECAL Brasil das regras internas de compliance e das políticas e procedimentos das áreas relacionadas ao programa de integridade. | E11: Recomendamos a implementação de uma rotina de divulgação do programa de integridade da empresa, comunicando para todos os funcionários sobre as políticas, código de ética e conduta, apresentação dos membros do comitê de compliance, data de realização das reuniões do comitê e resultados obtidos pelo comitê (respeitando os critérios de sigilo e confidencialidade). Recomendamos a criação de uma grade formal de treinamentos por área e cargo, disponível a todos os funcionários e gestores da DECAL Brasil relacionados a Compliance. | F11: 5 - Muito Alto | G11: Fraude | H11: 3 - Possível | I11: =(IF(F11="1 - Muito Baixo",1,IF(F11="2 - Baixo",2,IF(F11="3 - Médio",3,IF(F11="4 - Alto",4,IF(F11="5 - Muito Alto",5,0))))))*(IF(H11="1 - Raramente",1,IF(H11="2 - Pouco Provável",2,IF(H11="3 - Possível",3,IF(H11="4 - Muito provável",4,IF(H11="5 - Quase Certa ocorrência",5,0)))))) -> 15 | J11: =IF(I11=1,"Baixo (1)",IF(I11=2,"Baixo (2)",IF(I11=3,"Baixo (3)",IF(I11=4,"Baixo (4)",IF(I11=5,"Médio (5)",IF(I11=6,"Médio (6)",IF(I11=8,"Médio (8)",IF(I11=9,"Médio (9)",IF(I11=10,"Alto (10)",IF(I11=12,"Alto (12)",IF(I11=15,"Alto (15)",IF(I11=16,"Alto (16)",IF(I11=20,"Muito Alto (20)",IF(I11=25,"Muito Alto (25)","Erro")))))))))))))) -> Alto (15)
B12: R.COM.05 | C12: Compliance | D12: Risco de desconhecimento dos terceirizados da DECAL Brasil sobre o programa interno de integridade da empresa. | E12: Recomendamos que, no momento da contratação e início das atividades de qualquer funcionário terceirizado da DECAL Brasil, todas as regras de compliance sejam devidamente comunicadas e seja solicitada uma confirmação formal de ciência. | F12: 4 - Alto | G12: Fraude | H12: 3 - Possível | I12: =(IF(F12="1 - Muito Baixo",1,IF(F12="2 - Baixo",2,IF(F12="3 - Médio",3,IF(F12="4 - Alto",4,IF(F12="5 - Muito Alto",5,0))))))*(IF(H12="1 - Raramente",1,IF(H12="2 - Pouco Provável",2,IF(H12="3 - Possível",3,IF(H12="4 - Muito provável",4,IF(H12="5 - Quase Certa ocorrência",5,0)))))) -> 12 | J12: =IF(I12=1,"Baixo (1)",IF(I12=2,"Baixo (2)",IF(I12=3,"Baixo (3)",IF(I12=4,"Baixo (4)",IF(I12=5,"Médio (5)",IF(I12=6,"Médio (6)",IF(I12=8,"Médio (8)",IF(I12=9,"Médio (9)",IF(I12=10,"Alto (10)",IF(I12=12,"Alto (12)",IF(I12=15,"Alto (15)",IF(I12=16,"Alto (16)",IF(I12=20,"Muito Alto (20)",IF(I12=25,"Muito Alto (25)","Erro")))))))))))))) -> Alto (12)
B13: R.COM.06 | C13: Compliance | D13: Risco de desconhecimento pelos funcionários da DECAL Brasil sobre as regras de compliance dos órgãos públicos que possuem relacionamento com a empresa. | E13: Recomendamos que para todos os relacionamentos com órgãos públicos a DECAL deve avaliar as regras de compliance do agente para garantir o cumprimento das mais restritivas. | F13: 5 - Muito Alto | G13: Fraude | H13: 3 - Possível | I13: =(IF(F13="1 - Muito Baixo",1,IF(F13="2 - Baixo",2,IF(F13="3 - Médio",3,IF(F13="4 - Alto",4,IF(F13="5 - Muito Alto",5,0))))))*(IF(H13="1 - Raramente",1,IF(H13="2 - Pouco Provável",2,IF(H13="3 - Possível",3,IF(H13="4 - Muito provável",4,IF(H13="5 - Quase Certa ocorrência",5,0)))))) -> 15 | J13: =IF(I13=1,"Baixo (1)",IF(I13=2,"Baixo (2)",IF(I13=3,"Baixo (3)",IF(I13=4,"Baixo (4)",IF(I13=5,"Médio (5)",IF(I13=6,"Médio (6)",IF(I13=8,"Médio (8)",IF(I13=9,"Médio (9)",IF(I13=10,"Alto (10)",IF(I13=12,"Alto (12)",IF(I13=15,"Alto (15)",IF(I13=16,"Alto (16)",IF(I13=20,"Muito Alto (20)",IF(I13=25,"Muito Alto (25)","Erro")))))))))))))) -> Alto (15)
B14: R.COM.07 | C14: Compliance | D14: Risco de desatualização legal das regras de compliance da DECAL Brasil. | E14: Recomendamos que a área de compliance deve monitorar as atualizações legais da Lei Anticorrupção para adequação do seu programa interno. | F14: 5 - Muito Alto | G14: Consideramos para a probabilidade: Fraude e Corrupção | H14: 3 - Possível | I14: =(IF(F14="1 - Muito Baixo",1,IF(F14="2 - Baixo",2,IF(F14="3 - Médio",3,IF(F14="4 - Alto",4,IF(F14="5 - Muito Alto",5,0))))))*(IF(H14="1 - Raramente",1,IF(H14="2 - Pouco Provável",2,IF(H14="3 - Possível",3,IF(H14="4 - Muito provável",4,IF(H14="5 - Quase Certa ocorrência",5,0)))))) -> 15 | J14: =IF(I14=1,"Baixo (1)",IF(I14=2,"Baixo (2)",IF(I14=3,"Baixo (3)",IF(I14=4,"Baixo (4)",IF(I14=5,"Médio (5)",IF(I14=6,"Médio (6)",IF(I14=8,"Médio (8)",IF(I14=9,"Médio (9)",IF(I14=10,"Alto (10)",IF(I14=12,"Alto (12)",IF(I14=15,"Alto (15)",IF(I14=16,"Alto (16)",IF(I14=20,"Muito Alto (20)",IF(I14=25,"Muito Alto (25)","Erro")))))))))))))) -> Alto (15)
B15: R.COM.08 | C15: Compliance | D15: Risco de realização de transações com funcionários públicos, ex-funcionários públicos ou órgãos governamentais com relacionamento direto com funcionários da DECAL Brasil (ex.: parentes, amigos, etc.), desrespeitando as regras de independência da empresa. | E15: Recomendamos que seja realizado o mapeamento de conflitos de interesses de funcionários da DECAL Brasil e que todos as relações consideradas como de risco sejam acompanhadas pela área de compliance | F15: 5 - Muito Alto | G15: Corrupção | H15: 3 - Possível | I15: =(IF(F15="1 - Muito Baixo",1,IF(F15="2 - Baixo",2,IF(F15="3 - Médio",3,IF(F15="4 - Alto",4,IF(F15="5 - Muito Alto",5,0))))))*(IF(H15="1 - Raramente",1,IF(H15="2 - Pouco Provável",2,IF(H15="3 - Possível",3,IF(H15="4 - Muito provável",4,IF(H15="5 - Quase Certa ocorrência",5,0)))))) -> 15 | J15: =IF(I15=1,"Baixo (1)",IF(I15=2,"Baixo (2)",IF(I15=3,"Baixo (3)",IF(I15=4,"Baixo (4)",IF(I15=5,"Médio (5)",IF(I15=6,"Médio (6)",IF(I15=8,"Médio (8)",IF(I15=9,"Médio (9)",IF(I15=10,"Alto (10)",IF(I15=12,"Alto (12)",IF(I15=15,"Alto (15)",IF(I15=16,"Alto (16)",IF(I15=20,"Muito Alto (20)",IF(I15=25,"Muito Alto (25)","Erro")))))))))))))) -> Alto (15)
B16: R.COM.09 | C16: Compliance | D16: Risco de pagamentos ou doações indevidas para partidos políticos de acordo com a Lei Anticorrupção e em desacordo com a Reforma Eleitoral (Lei nº 13.165/2015). | E16: Recomendamos que seja implementado procedimentos para evitar o pagamento ou doação para partidos política em desacordo com a Reforma Eleitoral | F16: 1 - Muito Baixo | G16: Corrupção | H16: 3 - Possível | I16: =(IF(F16="1 - Muito Baixo",1,IF(F16="2 - Baixo",2,IF(F16="3 - Médio",3,IF(F16="4 - Alto",4,IF(F16="5 - Muito Alto",5,0))))))*(IF(H16="1 - Raramente",1,IF(H16="2 - Pouco Provável",2,IF(H16="3 - Possível",3,IF(H16="4 - Muito provável",4,IF(H16="5 - Quase Certa ocorrência",5,0)))))) -> 3 | J16: =IF(I16=1,"Baixo (1)",IF(I16=2,"Baixo (2)",IF(I16=3,"Baixo (3)",IF(I16=4,"Baixo (4)",IF(I16=5,"Médio (5)",IF(I16=6,"Médio (6)",IF(I16=8,"Médio (8)",IF(I16=9,"Médio (9)",IF(I16=10,"Alto (10)",IF(I16=12,"Alto (12)",IF(I16=15,"Alto (15)",IF(I16=16,"Alto (16)",IF(I16=20,"Muito Alto (20)",IF(I16=25,"Muito Alto (25)","Erro")))))))))))))) -> Baixo (3)
B17: R.COM.10 | C17: Compliance | D17: Risco de pagamentos ou concessão de hospitalidade, presentes ou brindes para servidores públicos em desacordo com o código de conduta da DECAL Brasil, código de conduta do órgão público, a lei anticorrupção ou com o "Código de Conduta da Alta Administração Federal". | E17: Recomendamos que todas as concessões de hospitalidade, presentes ou brindes para servidores públicos sejam realizadas mediante aprovação prévia do comitê de compliance e em adequação ao código de conduta da DECAL Brasil, código de conduto do órgão público, a lei anticorrupção ou com o "Código de Conduta da Alta Administração Federal". As regras para os casos onde a concessão da hospitalidade, presentes ou brindes é aceita devem estar devidamente formalizadas nas políticas da empresa e respeitando a regra mais restritiva. | F17: 1 - Muito Baixo | G17: Corrupção | H17: 3 - Possível | I17: =(IF(F17="1 - Muito Baixo",1,IF(F17="2 - Baixo",2,IF(F17="3 - Médio",3,IF(F17="4 - Alto",4,IF(F17="5 - Muito Alto",5,0))))))*(IF(H17="1 - Raramente",1,IF(H17="2 - Pouco Provável",2,IF(H17="3 - Possível",3,IF(H17="4 - Muito provável",4,IF(H17="5 - Quase Certa ocorrência",5,0)))))) -> 3 | J17: =IF(I17=1,"Baixo (1)",IF(I17=2,"Baixo (2)",IF(I17=3,"Baixo (3)",IF(I17=4,"Baixo (4)",IF(I17=5,"Médio (5)",IF(I17=6,"Médio (6)",IF(I17=8,"Médio (8)",IF(I17=9,"Médio (9)",IF(I17=10,"Alto (10)",IF(I17=12,"Alto (12)",IF(I17=15,"Alto (15)",IF(I17=16,"Alto (16)",IF(I17=20,"Muito Alto (20)",IF(I17=25,"Muito Alto (25)","Erro")))))))))))))) -> Baixo (3)
B18: R.COM.11 | C18: Compliance | D18: Risco de não monitoramento dos funcionários com ausência de independência com agentes públicos, ex-agentes públicos, órgãos regulamentares ou empresas privadas. | E18: Recomendamos que no mínimo a cada 12 meses, sejam realizadas atualizações do mapa de independência de todos os funcionários da DECAL Brasil. Adicionalmente, inclusão nas políticas de RH da obrigatoriedade de comunicação formal e tempestiva por parte dos funcionários de possíveis conflitos de relacionamentos. | F18: 5 - Muito Alto | G18: Agentes públicos | H18: 4 - Muito provável | I18: =(IF(F18="1 - Muito Baixo",1,IF(F18="2 - Baixo",2,IF(F18="3 - Médio",3,IF(F18="4 - Alto",4,IF(F18="5 - Muito Alto",5,0))))))*(IF(H18="1 - Raramente",1,IF(H18="2 - Pouco Provável",2,IF(H18="3 - Possível",3,IF(H18="4 - Muito provável",4,IF(H18="5 - Quase Certa ocorrência",5,0)))))) -> 20 | J18: =IF(I18=1,"Baixo (1)",IF(I18=2,"Baixo (2)",IF(I18=3,"Baixo (3)",IF(I18=4,"Baixo (4)",IF(I18=5,"Médio (5)",IF(I18=6,"Médio (6)",IF(I18=8,"Médio (8)",IF(I18=9,"Médio (9)",IF(I18=10,"Alto (10)",IF(I18=12,"Alto (12)",IF(I18=15,"Alto (15)",IF(I18=16,"Alto (16)",IF(I18=20,"Muito Alto (20)",IF(I18=25,"Muito Alto (25)","Erro")))))))))))))) -> Muito Alto (20)
B19: R.COM.12 | C19: Compliance | D19: Risco de ausência de apoio da alta administração para as regras de compliance da empresa. | E19: Recomendamos que no mínimo a cada 12 meses, seja realizada uma comunicação formal sobre a adesão dos membros da alta administração e do comitê de compliance às atualizações realizadas nas políticas de compliance da empresa. | F19: 5 - Muito Alto | G19: Fraude e Corrupção | H19: 3 - Possível | I19: =(IF(F19="1 - Muito Baixo",1,IF(F19="2 - Baixo",2,IF(F19="3 - Médio",3,IF(F19="4 - Alto",4,IF(F19="5 - Muito Alto",5,0))))))*(IF(H19="1 - Raramente",1,IF(H19="2 - Pouco Provável",2,IF(H19="3 - Possível",3,IF(H19="4 - Muito provável",4,IF(H19="5 - Quase Certa ocorrência",5,0)))))) -> 15 | J19: =IF(I19=1,"Baixo (1)",IF(I19=2,"Baixo (2)",IF(I19=3,"Baixo (3)",IF(I19=4,"Baixo (4)",IF(I19=5,"Médio (5)",IF(I19=6,"Médio (6)",IF(I19=8,"Médio (8)",IF(I19=9,"Médio (9)",IF(I19=10,"Alto (10)",IF(I19=12,"Alto (12)",IF(I19=15,"Alto (15)",IF(I19=16,"Alto (16)",IF(I19=20,"Muito Alto (20)",IF(I19=25,"Muito Alto (25)","Erro")))))))))))))) -> Alto (15)
... B25: R.COM.18 | C25: Compliance | D25: Risco de ausência de segregação de função entre membros do comitê e suas atividades operacionais (ex.: nenhum membro do comitê pode utilizar da prerrogativa de acumular mais de uma cargo como aprovador). | E25: Recomendamos que, para todos os casos onde um mesmo funcionário acumule as prerrogativas de aprovador de negócio (ex.: Gerente de Compras) e aprovador como membro do comitê, deve ser realizada a imediata definição de um membro do comitê de compliance substituto como aprovador. | F25: 5 - Muito Alto | G25: Fraude e Corrupção | H25: 3 - Possível | I25: =(IF(F25="1 - Muito Baixo",1,IF(F25="2 - Baixo",2,IF(F25="3 - Médio",3,IF(F25="4 - Alto",4,IF(F25="5 - Muito Alto",5,0))))))*(IF(H25="1 - Raramente",1,IF(H25="2 - Pouco Provável",2,IF(H25="3 - Possível",3,IF(H25="4 - Muito provável",4,IF(H25="5 - Quase Certa ocorrência",5,0)))))) -> 15 | J25: =IF(I25=1,"Baixo (1)",IF(I25=2,"Baixo (2)",IF(I25=3,"Baixo (3)",IF(I25=4,"Baixo (4)",IF(I25=5,"Médio (5)",IF(I25=6,"Médio (6)",IF(I25=8,"Médio (8)",IF(I25=9,"Médio (9)",IF(I25=10,"Alto (10)",IF(I25=12,"Alto (12)",IF(I25=15,"Alto (15)",IF(I25=16,"Alto (16)",IF(I25=20,"Muito Alto (20)",IF(I25=25,"Muito Alto (25)","Erro")))))))))))))) -> Alto (15)
S28: Probabilidade

Sheet Compras e Contas a Pagar
F7: Análise de Risco
B8: Ref. | C8: Processo | D8: Risco | E8: Recomendação | F8: Impacto | G8: Classificação do Risco | H8: Probabilidade | I8: Cálculo | J8: Análise de Risco
B9: R.CCP.01 | C9: Compras e Contas a Pagar | D9: Risco de conflito de interesse na contratação de fornecedores e consultores (agentes públicos, ex-agentes públicos, órgãos reguladores, órgãos fiscalizadores ou empresas privadas). | E9: Recomendamos que, na etapa de contratação de fornecedores, seja realizada uma avaliação dos relacionamentos destes com funcionários da DECAL Brasil e seus clientes e, caso identificada alguma inconformidade (conflito de interesse), a contratação fique sujeita a uma aprovação do comitê de compliance (para acompanhamento e tratativa do risco). Recomendamos que todas as negociações da DECAL Brasil que envolvam agentes públicos sejam realizadas por mais de um membro da empresa e estas devem passar por avaliação e aprovação do comitê de compliance. | F9: 5 - Muito Alto | G9: Corrupção e Agentes públicos | H9: 4 - Muito provável | I9: =(IF(F9="1 - Muito Baixo",1,IF(F9="2 - Baixo",2,IF(F9="3 - Médio",3,IF(F9="4 - Alto",4,IF(F9="5 - Muito Alto",5,0))))))*(IF(H9="1 - Raramente",1,IF(H9="2 - Pouco Provável",2,IF(H9="3 - Possível",3,IF(H9="4 - Muito provável",4,IF(H9="5 - Quase Certa ocorrência",5,0)))))) -> 20 | J9: =IF(I9=1,"Baixo (1)",IF(I9=2,"Baixo (2)",IF(I9=3,"Baixo (3)",IF(I9=4,"Baixo (4)",IF(I9=5,"Médio (5)",IF(I9=6,"Médio (6)",IF(I9=8,"Médio (8)",IF(I9=9,"Médio (9)",IF(I9=10,"Alto (10)",IF(I9=12,"Alto (12)",IF(I9=15,"Alto (15)",IF(I9=16,"Alto (16)",IF(I9=20,"Muito Alto (20)",IF(I9=25,"Muito Alto (25)","Erro")))))))))))))) -> Muito Alto (20)
B10: R.CCP.02 | C10: Compras e Contas a Pagar | D10: Risco de pagamentos indevidos para obtenção de vantagens competitivas ou técnicas com agentes públicos, ex-agentes públicos, órgãos reguladores, órgãos fiscalizadores ou empresas privadas. | E10: Recomendamos que todos os pagamentos realizados para agentes públicos, ex-agentes públicos, órgãos reguladores ou empresas privadas, sejam realizados somente mediante processos claros de cotação e avaliação de melhores preços, além de capacidade técnica. Caso a capacidade técnica seja considerada para a escolha de uma proposta com preço superior às concorrentes, esta deve ter embasamento técnico da área contratante e aprovação do comitê de compliance. | F10: 5 - Muito Alto | G10: Corrupção e Agentes públicos | H10: 4 - Muito provável | I10: =(IF(F10="1 - Muito Baixo",1,IF(F10="2 - Baixo",2,IF(F10="3 - Médio",3,IF(F10="4 - Alto",4,IF(F10="5 - Muito Alto",5,0))))))*(IF(H10="1 - Raramente",1,IF(H10="2 - Pouco Provável",2,IF(H10="3 - Possível",3,IF(H10="4 - Muito provável",4,IF(H10="5 - Quase Certa ocorrência",5,0)))))) -> 20 | J10: =IF(I10=1,"Baixo (1)",IF(I10=2,"Baixo (2)",IF(I10=3,"Baixo (3)",IF(I10=4,"Baixo (4)",IF(I10=5,"Médio (5)",IF(I10=6,"Médio (6)",IF(I10=8,"Médio (8)",IF(I10=9,"Médio (9)",IF(I10=10,"Alto (10)",IF(I10=12,"Alto (12)",IF(I10=15,"Alto (15)",IF(I10=16,"Alto (16)",IF(I10=20,"Muito Alto (20)",IF(I10=25,"Muito Alto (25)","Erro")))))))))))))) -> Muito Alto (20)
B11: R.CCP.03 | C11: Compras e Contas a Pagar | D11: Risco de pagamentos realizados em valores divergentes aos contratados com agentes públicos, ex-agentes públicos, órgãos regulamentares ou empresas privadas (superfaturamento ou subfaturamento de contratos). | E11: Recomendamos que, antes da realização dos pagamentos, seja realizada uma validação dos valores acordados no contrato ou pedido de compra com o valor da nota fiscal emitida pelo fornecedor (agentes públicos, ex-agentes públicos, órgãos reguladores ou empresas privadas) de acordo com alçadas para aprovadores das áreas de Contas a Pagar e comitê de compliance. | F11: 5 - Muito Alto | G11: Fraude | H11: 3 - Possível | I11: =(IF(F11="1 - Muito Baixo",1,IF(F11="2 - Baixo",2,IF(F11="3 - Médio",3,IF(F11="4 - Alto",4,IF(F11="5 - Muito Alto",5,0))))))*(IF(H11="1 - Raramente",1,IF(H11="2 - Pouco Provável",2,IF(H11="3 - Possível",3,IF(H11="4 - Muito provável",4,IF(H11="5 - Quase Certa ocorrência",5,0)))))) -> 15 | J11: =IF(I11=1,"Baixo (1)",IF(I11=2,"Baixo (2)",IF(I11=3,"Baixo (3)",IF(I11=4,"Baixo (4)",IF(I11=5,"Médio (5)",IF(I11=6,"Médio (6)",IF(I11=8,"Médio (8)",IF(I11=9,"Médio (9)",IF(I11=10,"Alto (10)",IF(I11=12,"Alto (12)",IF(I11=15,"Alto (15)",IF(I11=16,"Alto (16)",IF(I11=20,"Muito Alto (20)",IF(I11=25,"Muito Alto (25)","Erro")))))))))))))) -> Alto (15)
B12: R.CCP.04 | C12: Compras e Contas a Pagar | D12: Risco de pagamentos realizados sem as aprovações devidas da administração da DECAL Brasil para agentes públicos, ex-agentes públicos, órgãos reguladores, órgãos fiscalizadores ou empresas privadas. | E12: Recomendamos que os pagamentos somente sejam realizados mediante alçada de aprovação definida pela DECAL Brasil, conforme regras de negócio, inclusive com o envolvimento da equipe de compliance para os casos onde algum risco adicional (ex: conflito de interesse, pagamentos de valores adicionais) sejam identificados. | F12: 5 - Muito Alto | G12: Fraude | H12: 3 - Possível | I12: =(IF(F12="1 - Muito Baixo",1,IF(F12="2 - Baixo",2,IF(F12="3 - Médio",3,IF(F12="4 - Alto",4,IF(F12="5 - Muito Alto",5,0))))))*(IF(H12="1 - Raramente",1,IF(H12="2 - Pouco Provável",2,IF(H12="3 - Possível",3,IF(H12="4 - Muito provável",4,IF(H12="5 - Quase Certa ocorrência",5,0)))))) -> 15 | J12: =IF(I12=1,"Baixo (1)",IF(I12=2,"Baixo (2)",IF(I12=3,"Baixo (3)",IF(I12=4,"Baixo (4)",IF(I12=5,"Médio (5)",IF(I12=6,"Médio (6)",IF(I12=8,"Médio (8)",IF(I12=9,"Médio (9)",IF(I12=10,"Alto (10)",IF(I12=12,"Alto (12)",IF(I12=15,"Alto (15)",IF(I12=16,"Alto (16)",IF(I12=20,"Muito Alto (20)",IF(I12=25,"Muito Alto (25)","Erro")))))))))))))) -> Alto (15)
B13: R.CCP.05 | C13: Compras e Contas a Pagar | D13: Risco de pagamentos realizados sem a prestação do serviço ou entrega de mercadoria por agentes públicos, ex-agentes públicos e empresas privadas. | E13: Recomendamos que todos os pagamentos realizados para agentes públicos, ex-agentes públicos, órgãos reguladores ou empresas privadas, sejam realizados somente mediante comprovação formal da realização do serviço, entrega da mercadoria e atestação da qualidade pela área contratante e pelo comitê de compliance. | F13: 5 - Muito Alto | G13: Fraude, Corrupção e Agentes Públicos | H13: 4 - Muito provável | I13: =(IF(F13="1 - Muito Baixo",1,IF(F13="2 - Baixo",2,IF(F13="3 - Médio",3,IF(F13="4 - Alto",4,IF(F13="5 - Muito Alto",5,0))))))*(IF(H13="1 - Raramente",1,IF(H13="2 - Pouco Provável",2,IF(H13="3 - Possível",3,IF(H13="4 - Muito provável",4,IF(H13="5 - Quase Certa ocorrência",5,0)))))) -> 20 | J13: =IF(I13=1,"Baixo (1)",IF(I13=2,"Baixo (2)",IF(I13=3,"Baixo (3)",IF(I13=4,"Baixo (4)",IF(I13=5,"Médio (5)",IF(I13=6,"Médio (6)",IF(I13=8,"Médio (8)",IF(I13=9,"Médio (9)",IF(I13=10,"Alto (10)",IF(I13=12,"Alto (12)",IF(I13=15,"Alto (15)",IF(I13=16,"Alto (16)",IF(I13=20,"Muito Alto (20)",IF(I13=25,"Muito Alto (25)","Erro")))))))))))))) -> Muito Alto (20)
B14: R.CCP.06 | C14: Compras e Contas a Pagar | D14: Risco de pagamentos indevidos de taxas, adicionais/extras aos valores (ex.: juros, impostos) realizados para agentes públicos, ex-agentes públicos, órgãos reguladores, órgãos fiscalizadores ou empresas privadas, com intenção de obtenção de vantagem indevida. | E14: Recomendamos que todos os pagamentos de adicionais/extras ou taxas para agentes públicos, ex-agentes públicos ou órgãos reguladores sejam realizados somente mediante aprovação formal da área de compliance e justificativas formalizadas pela área contratante. | F14: 2 - Baixo | G14: Fraude, Corrupção e Agentes Públicos | H14: 4 - Muito provável | I14: =(IF(F14="1 - Muito Baixo",1,IF(F14="2 - Baixo",2,IF(F14="3 - Médio",3,IF(F14="4 - Alto",4,IF(F14="5 - Muito Alto",5,0))))))*(IF(H14="1 - Raramente",1,IF(H14="2 - Pouco Provável",2,IF(H14="3 - Possível",3,IF(H14="4 - Muito provável",4,IF(H14="5 - Quase Certa ocorrência",5,0)))))) -> 8 | J14: =IF(I14=1,"Baixo (1)",IF(I14=2,"Baixo (2)",IF(I14=3,"Baixo (3)",IF(I14=4,"Baixo (4)",IF(I14=5,"Médio (5)",IF(I14=6,"Médio (6)",IF(I14=8,"Médio (8)",IF(I14=9,"Médio (9)",IF(I14=10,"Alto (10)",IF(I14=12,"Alto (12)",IF(I14=15,"Alto (15)",IF(I14=16,"Alto (16)",IF(I14=20,"Muito Alto (20)",IF(I14=25,"Muito Alto (25)","Erro")))))))))))))) -> Médio (8)
B15: R.CCP.07 | C15: Compras e Contas a Pagar | D15: Risco de contratação de empresas citadas em listas de empresas inidôneas (CIES - Cadastro Nacional Empresas Inidôneas e Suspensas, CNEP - Cadastro Nacional de Empresa Punidas, Pessoas Politicamente Expostas - PPE). | E15: Recomendamos que, antes da contratação de qualquer fornecedor (agentes públicos, ex-agentes públicos, órgãos regulamentares ou empresas privadas), uma análise de Due Dilligence seja realizada, inclusive através de consulta a cadastros nacionais de empresas (ex: CIES - Cadastro Nacional Empresas Inidôneas e Suspensas, CNEP - Cadastro Nacional de Empresa Punidas, Pessoas Politicamente Expostas - PPE). Caso seja identificado algum registro do fornecedor, sua contratação somente pode ser realizada mediante avaliação formal do comitê de compliance com apresentação de justificativas formais. | F15: 5 - Muito Alto | G15: Clientes e Fornecedores | H15: 4 - Muito provável | I15: =(IF(F15="1 - Muito Baixo",1,IF(F15="2 - Baixo",2,IF(F15="3 - Médio",3,IF(F15="4 - Alto",4,IF(F15="5 - Muito Alto",5,0))))))*(IF(H15="1 - Raramente",1,IF(H15="2 - Pouco Provável",2,IF(H15="3 - Possível",3,IF(H15="4 - Muito provável",4,IF(H15="5 - Quase Certa ocorrência",5,0)))))) -> 20 | J15: =IF(I15=1,"Baixo (1)",IF(I15=2,"Baixo (2)",IF(I15=3,"Baixo (3)",IF(I15=4,"Baixo (4)",IF(I15=5,"Médio (5)",IF(I15=6,"Médio (6)",IF(I15=8,"Médio (8)",IF(I15=9,"Médio (9)",IF(I15=10,"Alto (10)",IF(I15=12,"Alto (12)",IF(I15=15,"Alto (15)",IF(I15=16,"Alto (16)",IF(I15=20,"Muito Alto (20)",IF(I15=25,"Muito Alto (25)","Erro")))))))))))))) -> Muito Alto (20)
B16: R.CCP.08 | C16: Compras e Contas a Pagar | D16: Risco de transgressão das regras anticorrupção por fornecedores e/ou terceirizados contratados pela DECAL Brasil na prestação de serviços junto a agentes públicos, ex-agentes públicos, órgãos regulamentares ou empresas privadas. | E16: Recomendamos que em todos os contratos com empresas fornecedoras e/ou terceirizadas sejam incluídas cláusulas de responsabilidade e adequação às leis anticorrupção. | F16: 5 - Muito Alto | G16: Corrupção e Agentes públicos | H16: 4 - Muito provável | I16: =(IF(F16="1 - Muito Baixo",1,IF(F16="2 - Baixo",2,IF(F16="3 - Médio",3,IF(F16="4 - Alto",4,IF(F16="5 - Muito Alto",5,0))))))*(IF(H16="1 - Raramente",1,IF(H16="2 - Pouco Provável",2,IF(H16="3 - Possível",3,IF(H16="4 - Muito provável",4,IF(H16="5 - Quase Certa ocorrência",5,0)))))) -> 20 | J16: =IF(I16=1,"Baixo (1)",IF(I16=2,"Baixo (2)",IF(I16=3,"Baixo (3)",IF(I16=4,"Baixo (4)",IF(I16=5,"Médio (5)",IF(I16=6,"Médio (6)",IF(I16=8,"Médio (8)",IF(I16=9,"Médio (9)",IF(I16=10,"Alto (10)",IF(I16=12,"Alto (12)",IF(I16=15,"Alto (15)",IF(I16=16,"Alto (16)",IF(I16=20,"Muito Alto (20)",IF(I16=25,"Muito Alto (25)","Erro")))))))))))))) -> Muito Alto (20)

Sheet Contabilidade
F6: Análise de Risco
B7: Ref. | C7: Processo | D7: Risco | E7: Recomendação | F7: Impacto | G7: Classificação do Risco | H7: Probabilidade | I7: Cálculo | J7: Análise de Risco
B8: R.CON.01 | C8: Contabilidade | D8: Risco de registros contábeis em desacordo com a Lei Anticorrupção | E8: Recomendamos que todos os registros contábeis sejam de fácil identificação em conformidade com a Lei Anticorrupção. | F8: 5 - Muito Alto | G8: Fraude | H8: 3 - Possível | I8: =(IF(F8="1 - Muito Baixo",1,IF(F8="2 - Baixo",2,IF(F8="3 - Médio",3,IF(F8="4 - Alto",4,IF(F8="5 - Muito Alto",5,0))))))*(IF(H8="1 - Raramente",1,IF(H8="2 - Pouco Provável",2,IF(H8="3 - Possível",3,IF(H8="4 - Muito provável",4,IF(H8="5 - Quase Certa ocorrência",5,0)))))) -> 15 | J8: =IF(I8=1,"Baixo (1)",IF(I8=2,"Baixo (2)",IF(I8=3,"Baixo (3)",IF(I8=4,"Baixo (4)",IF(I8=5,"Médio (5)",IF(I8=6,"Médio (6)",IF(I8=8,"Médio (8)",IF(I8=9,"Médio (9)",IF(I8=10,"Alto (10)",IF(I8=12,"Alto (12)",IF(I8=15,"Alto (15)",IF(I8=16,"Alto (16)",IF(I8=20,"Muito Alto (20)",IF(I8=25,"Muito Alto (25)","Erro")))))))))))))) -> Alto (15)

Sheet Licenças
F6: Análise de Risco
B7: Ref. | C7: Processo | D7: Risco | E7: Recomendação | F7: Impacto | G7: Classificação do Risco | H7: Probabilidade | I7: Cálculo | J7: Análise de Risco
B8: R.LIC.01 | C8: Licenças | D8: Risco de transgressão das regras de compliance para obtenção das licenças junto às agências, órgãos reguladores e órgãos fiscalizadores da DECAL Brasil: a) Agentes Públicos; b) Ex-agentes públicos; c) Agência nacional de petróleo (ANP); d) Companhia Pernambucana de Recursos Hídricos (CPRH); e) Agência Nacional de Transportes Aquaviários (ANTAQ); f) Governo Federal; g) Governo Estadual; h) Governo Municipal; i) Receita Federal; j) Porto de Suape. | E8: Recomendamos que todo o processo e requerimentos para obtenção de licenças sejam descritos em políticas de forma clara e disponibilizados para todos os envolvidos. Recomendamos que membros da equipe do comitês de compliance acompanhem o processo de obtenção das licenças da DECAL Brasil. | F8: 2 - Baixo | G8: "Agentes públicos" e "Meio Ambiente e Segurança do trabalho" | H8: 4 - Muito provável | I8: =(IF(F8="1 - Muito Baixo",1,IF(F8="2 - Baixo",2,IF(F8="3 - Médio",3,IF(F8="4 - Alto",4,IF(F8="5 - Muito Alto",5,0))))))*(IF(H8="1 - Raramente",1,IF(H8="2 - Pouco Provável",2,IF(H8="3 - Possível",3,IF(H8="4 - Muito provável",4,IF(H8="5 - Quase Certa ocorrência",5,0)))))) -> 8 | J8: =IF(I8=1,"Baixo (1)",IF(I8=2,"Baixo (2)",IF(I8=3,"Baixo (3)",IF(I8=4,"Baixo (4)",IF(I8=5,"Médio (5)",IF(I8=6,"Médio (6)",IF(I8=8,"Médio (8)",IF(I8=9,"Médio (9)",IF(I8=10,"Alto (10)",IF(I8=12,"Alto (12)",IF(I8=15,"Alto (15)",IF(I8=16,"Alto (16)",IF(I8=20,"Muito Alto (20)",IF(I8=25,"Muito Alto (25)","Erro")))))))))))))) -> Médio (8)
B9: R.LIC.02 | C9: Licenças | D9: Risco de ausência de independência entre os funcionários da DECAL Brasil com agentes das agências, órgãos reguladores e órgãos fiscalizadores: a) Agentes Públicos; b) ex-agentes públicos; c) Agência nacional de petróleo (ANP); d) Companhia Pernambucana de Recursos Hídricos (CPRH); e) Agência Nacional de Transportes Aquaviários (ANTAQ); f) Governo Federal; g) Governo Estadual; h) Governo Municipal; i) Receita Federal; j) Porto de Suape. | E9: Recomendamos o mapeamento de conflitos de interesse entre os responsáveis por realizar os procedimentos para obtenção das licenças e os agentes públicos, órgãos reguladores e órgãos fiscalizadores. Caso seja identificada a ausência de independência, este relacionamento deve ser monitorado pelo comitê de compliance. | F9: 2 - Baixo | G9: "Agentes públicos" e "Meio Ambiente e Segurança do trabalho" | H9: 4 - Muito provável | I9: =(IF(F9="1 - Muito Baixo",1,IF(F9="2 - Baixo",2,IF(F9="3 - Médio",3,IF(F9="4 - Alto",4,IF(F9="5 - Muito Alto",5,0))))))*(IF(H9="1 - Raramente",1,IF(H9="2 - Pouco Provável",2,IF(H9="3 - Possível",3,IF(H9="4 - Muito provável",4,IF(H9="5 - Quase Certa ocorrência",5,0)))))) -> 8 | J9: =IF(I9=1,"Baixo (1)",IF(I9=2,"Baixo (2)",IF(I9=3,"Baixo (3)",IF(I9=4,"Baixo (4)",IF(I9=5,"Médio (5)",IF(I9=6,"Médio (6)",IF(I9=8,"Médio (8)",IF(I9=9,"Médio (9)",IF(I9=10,"Alto (10)",IF(I9=12,"Alto (12)",IF(I9=15,"Alto (15)",IF(I9=16,"Alto (16)",IF(I9=20,"Muito Alto (20)",IF(I9=25,"Muito Alto (25)","Erro")))))))))))))) -> Médio (8)
B10: R.LIC.03 | C10: Licenças | D10: Risco de pagamentos indevidos de taxas para obtenção e manutenção das licenças junto as agências, órgãos reguladores e órgãos fiscalizadores da DECAL Brasil com o objetivo de obtenção de vantagem indevida: a) Agentes Públicos; b) ex-agentes públicos; c) Agência nacional de petróleo (ANP); d) Companhia Pernambucana de Recursos Hídricos (CPRH); e) Agência Nacional de Transportes Aquaviários (ANTAQ); f) Governo Federal; g) Governo Estadual; h) Governo Municipal; i) Receita Federal; j) Porto de Suape. | E10: Recomendamos que todos os pagamentos realizados para obtenção de licenças sejam monitorados pelo comitê de compliance. | F10: 2 - Baixo | G10: "Agentes públicos" e "Meio Ambiente e Segurança do trabalho" | H10: 4 - Muito provável | I10: =(IF(F10="1 - Muito Baixo",1,IF(F10="2 - Baixo",2,IF(F10="3 - Médio",3,IF(F10="4 - Alto",4,IF(F10="5 - Muito Alto",5,0))))))*(IF(H10="1 - Raramente",1,IF(H10="2 - Pouco Provável",2,IF(H10="3 - Possível",3,IF(H10="4 - Muito provável",4,IF(H10="5 - Quase Certa ocorrência",5,0)))))) -> 8 | J10: =IF(I10=1,"Baixo (1)",IF(I10=2,"Baixo (2)",IF(I10=3,"Baixo (3)",IF(I10=4,"Baixo (4)",IF(I10=5,"Médio (5)",IF(I10=6,"Médio (6)",IF(I10=8,"Médio (8)",IF(I10=9,"Médio (9)",IF(I10=10,"Alto (10)",IF(I10=12,"Alto (12)",IF(I10=15,"Alto (15)",IF(I10=16,"Alto (16)",IF(I10=20,"Muito Alto (20)",IF(I10=25,"Muito Alto (25)","Erro")))))))))))))) -> Médio (8)

Sheet Ope_Est_Man
F6: Análise de Risco
B7: Ref. | C7: Processo | D7: Risco | E7: Recomendação | F7: Impacto | G7: Classificação do Risco | H7: Probabilidade | I7: Cálculo | J7: Análise de Risco
B8: R.OPE.01 | C8: Operação/ Estoques/ Manutenção | D8: Risco de medições incorretas (ex.: quantidade, temperatura, pressão) intencionais de mercadoria nas movimentações por transporte rodoviário, com objetivo de obtenção de vantagem indevida. | E8: Recomendamos que todas as divergências identificadas nas medições sejam revisadas por um segundo funcionário da DECAL Brasil distinto através de conferência cega. | F8: 5 - Muito Alto | G8: "Propriedade intelectual e industrial" e "Fraude" | H8: 3 - Possível | I8: =(IF(F8="1 - Muito Baixo",1,IF(F8="2 - Baixo",2,IF(F8="3 - Médio",3,IF(F8="4 - Alto",4,IF(F8="5 - Muito Alto",5,0))))))*(IF(H8="1 - Raramente",1,IF(H8="2 - Pouco Provável",2,IF(H8="3 - Possível",3,IF(H8="4 - Muito provável",4,IF(H8="5 - Quase Certa ocorrência",5,0)))))) -> 15 | J8: =IF(I8=1,"Baixo (1)",IF(I8=2,"Baixo (2)",IF(I8=3,"Baixo (3)",IF(I8=4,"Baixo (4)",IF(I8=5,"Médio (5)",IF(I8=6,"Médio (6)",IF(I8=8,"Médio (8)",IF(I8=9,"Médio (9)",IF(I8=10,"Alto (10)",IF(I8=12,"Alto (12)",IF(I8=15,"Alto (15)",IF(I8=16,"Alto (16)",IF(I8=20,"Muito Alto (20)",IF(I8=25,"Muito Alto (25)","Erro")))))))))))))) -> Alto (15)
B9: R.OPE.02 | C9: Operação/ Estoques/ Manutenção | D9: Risco de medições incorretas (ex.: quantidade, temperatura, pressão) intencionais de mercadoria nas movimentações por transporte marítimo, com objetivo de obtenção de vantagem indevida. | E9: Recomendamos que todas as medições realizadas sejam revisadas por um segundo funcionário da DECAL Brasil e, caso alguma divergência seja identificada entre os dados reportados pelo cliente, ou equipe fiscalizadora, uma segunda conferência cega seja realizada. | F9: 5 - Muito Alto | G9: "Propriedade intelectual e industrial" e "Fraude" | H9: 3 - Possível | I9: =(IF(F9="1 - Muito Baixo",1,IF(F9="2 - Baixo",2,IF(F9="3 - Médio",3,IF(F9="4 - Alto",4,IF(F9="5 - Muito Alto",5,0))))))*(IF(H9="1 - Raramente",1,IF(H9="2 - Pouco Provável",2,IF(H9="3 - Possível",3,IF(H9="4 - Muito provável",4,IF(H9="5 - Quase Certa ocorrência",5,0)))))) -> 15 | J9: =IF(I9=1,"Baixo (1)",IF(I9=2,"Baixo (2)",IF(I9=3,"Baixo (3)",IF(I9=4,"Baixo (4)",IF(I9=5,"Médio (5)",IF(I9=6,"Médio (6)",IF(I9=8,"Médio (8)",IF(I9=9,"Médio (9)",IF(I9=10,"Alto (10)",IF(I9=12,"Alto (12)",IF(I9=15,"Alto (15)",IF(I9=16,"Alto (16)",IF(I9=20,"Muito Alto (20)",IF(I9=25,"Muito Alto (25)","Erro")))))))))))))) -> Alto (15)
B10: R.OPE.03 | C10: Operação/ Estoques/ Manutenção | D10: Risco de medições incorretas (ex.: quantidade, temperatura, pressão) intencionais de mercadoria nas movimentações por transporte dutoviário, com objetivo de obtenção de vantagem indevida. | E10: Recomendamos que todas as medições realizadas sejam revisadas por um segundo funcionário da DECAL Brasil e, caso alguma divergência seja identificada entre os dados reportados pelo cliente, ou equipe fiscalizadora, uma segunda conferência cega seja realizada. | F10: 5 - Muito Alto | G10: "Propriedade intelectual e industrial" e "Fraude" | H10: 3 - Possível | I10: =(IF(F10="1 - Muito Baixo",1,IF(F10="2 - Baixo",2,IF(F10="3 - Médio",3,IF(F10="4 - Alto",4,IF(F10="5 - Muito Alto",5,0))))))*(IF(H10="1 - Raramente",1,IF(H10="2 - Pouco Provável",2,IF(H10="3 - Possível",3,IF(H10="4 - Muito provável",4,IF(H10="5 - Quase Certa ocorrência",5,0)))))) -> 15 | J10: =IF(I10=1,"Baixo (1)",IF(I10=2,"Baixo (2)",IF(I10=3,"Baixo (3)",IF(I10=4,"Baixo (4)",IF(I10=5,"Médio (5)",IF(I10=6,"Médio (6)",IF(I10=8,"Médio (8)",IF(I10=9,"Médio (9)",IF(I10=10,"Alto (10)",IF(I10=12,"Alto (12)",IF(I10=15,"Alto (15)",IF(I10=16,"Alto (16)",IF(I10=20,"Muito Alto (20)",IF(I10=25,"Muito Alto (25)","Erro")))))))))))))) -> Alto (15)
B11: R.OPE.04 | C11: Operação/ Estoques/ Manutenção | D11: Risco de medições incorretas intencionais de qualidade e validação das quantidades em estoque (acompanhamento e validação dos estoques de mercadorias) para apresentação ao cliente, com objetivo de obtenção de vantagem indevida. | E11: Recomendamos que todas as medições realizadas sejam revisadas por um segundo funcionário da DECAL Brasil e, caso alguma divergência seja identificada entre os dados reportados pelo cliente, ou equipe fiscalizadora, uma segunda conferência cega seja realizada. | F11: 5 - Muito Alto | G11: "Propriedade intelectual e industrial" e "Fraude" | H11: 3 - Possível | I11: =(IF(F11="1 - Muito Baixo",1,IF(F11="2 - Baixo",2,IF(F11="3 - Médio",3,IF(F11="4 - Alto",4,IF(F11="5 - Muito Alto",5,0))))))*(IF(H11="1 - Raramente",1,IF(H11="2 - Pouco Provável",2,IF(H11="3 - Possível",3,IF(H11="4 - Muito provável",4,IF(H11="5 - Quase Certa ocorrência",5,0)))))) -> 15 | J11: =IF(I11=1,"Baixo (1)",IF(I11=2,"Baixo (2)",IF(I11=3,"Baixo (3)",IF(I11=4,"Baixo (4)",IF(I11=5,"Médio (5)",IF(I11=6,"Médio (6)",IF(I11=8,"Médio (8)",IF(I11=9,"Médio (9)",IF(I11=10,"Alto (10)",IF(I11=12,"Alto (12)",IF(I11=15,"Alto (15)",IF(I11=16,"Alto (16)",IF(I11=20,"Muito Alto (20)",IF(I11=25,"Muito Alto (25)","Erro")))))))))))))) -> Alto (15)
B12: R.OPE.05 | C12: Operação/ Estoques/ Manutenção | D12: Risco de medições incorretas intencionais, com objetivo de obtenção de vantagem indevida, ou furto de mercadoria nas drenagens dos tanques para limpeza. | E12: Recomendamos que todas as medições realizadas sejam revisadas por um segundo funcionário da DECAL Brasil e, caso alguma divergência seja identificada entre os dados reportados pelo cliente, ou equipe fiscalizadora, uma segunda conferência cega seja realizada. | F12: 5 - Muito Alto | G12: "Propriedade intelectual e industrial" e "Fraude" | H12: 3 - Possível | I12: =(IF(F12="1 - Muito Baixo",1,IF(F12="2 - Baixo",2,IF(F12="3 - Médio",3,IF(F12="4 - Alto",4,IF(F12="5 - Muito Alto",5,0))))))*(IF(H12="1 - Raramente",1,IF(H12="2 - Pouco Provável",2,IF(H12="3 - Possível",3,IF(H12="4 - Muito provável",4,IF(H12="5 - Quase Certa ocorrência",5,0)))))) -> 15 | J12: =IF(I12=1,"Baixo (1)",IF(I12=2,"Baixo (2)",IF(I12=3,"Baixo (3)",IF(I12=4,"Baixo (4)",IF(I12=5,"Médio (5)",IF(I12=6,"Médio (6)",IF(I12=8,"Médio (8)",IF(I12=9,"Médio (9)",IF(I12=10,"Alto (10)",IF(I12=12,"Alto (12)",IF(I12=15,"Alto (15)",IF(I12=16,"Alto (16)",IF(I12=20,"Muito Alto (20)",IF(I12=25,"Muito Alto (25)","Erro")))))))))))))) -> Alto (15)
B13: R.OPE.06 | C13: Operação/ Estoques/ Manutenção | D13: Risco de medições incorretas ou furto de mercadoria nas drenagens dos tanques para retiradas de água, com objetivo de obtenção de vantagem indevida. | E13: Recomendamos que todas as medições realizadas sejam revisadas por um segundo funcionário da DECAL Brasil e, caso alguma divergência seja identificada entre os dados reportados pelo cliente, ou equipe fiscalizadora, uma segunda conferência cega seja realizada. | F13: 5 - Muito Alto | G13: "Propriedade intelectual e industrial" e "Fraude" | H13: 3 - Possível | I13: =(IF(F13="1 - Muito Baixo",1,IF(F13="2 - Baixo",2,IF(F13="3 - Médio",3,IF(F13="4 - Alto",4,IF(F13="5 - Muito Alto",5,0))))))*(IF(H13="1 - Raramente",1,IF(H13="2 - Pouco Provável",2,IF(H13="3 - Possível",3,IF(H13="4 - Muito provável",4,IF(H13="5 - Quase Certa ocorrência",5,0)))))) -> 15 | J13: =IF(I13=1,"Baixo (1)",IF(I13=2,"Baixo (2)",IF(I13=3,"Baixo (3)",IF(I13=4,"Baixo (4)",IF(I13=5,"Médio (5)",IF(I13=6,"Médio (6)",IF(I13=8,"Médio (8)",IF(I13=9,"Médio (9)",IF(I13=10,"Alto (10)",IF(I13=12,"Alto (12)",IF(I13=15,"Alto (15)",IF(I13=16,"Alto (16)",IF(I13=20,"Muito Alto (20)",IF(I13=25,"Muito Alto (25)","Erro")))))))))))))) -> Alto (15)
B14: R.OPE.07 | C14: Operação/ Estoques/ Manutenção | D14: Risco de divergências nas medições pelo descumprimento de requisitos técnicos (ex.: tempo mínimo de repouso do material). | E14: Recomendamos a implementação de controles de monitoramento para garantir o cumprimento de todos os requisitos técnicos para realização de medições (ex.: tempo mínimo de repouso) ou aprovação formal do cliente em caso de descumprimento. | F14: 5 - Muito Alto | G14: "Propriedade intelectual e industrial" e "Fraude" | H14: 3 - Possível | I14: =(IF(F14="1 - Muito Baixo",1,IF(F14="2 - Baixo",2,IF(F14="3 - Médio",3,IF(F14="4 - Alto",4,IF(F14="5 - Muito Alto",5,0))))))*(IF(H14="1 - Raramente",1,IF(H14="2 - Pouco Provável",2,IF(H14="3 - Possível",3,IF(H14="4 - Muito provável",4,IF(H14="5 - Quase Certa ocorrência",5,0)))))) -> 15 | J14: =IF(I14=1,"Baixo (1)",IF(I14=2,"Baixo (2)",IF(I14=3,"Baixo (3)",IF(I14=4,"Baixo (4)",IF(I14=5,"Médio (5)",IF(I14=6,"Médio (6)",IF(I14=8,"Médio (8)",IF(I14=9,"Médio (9)",IF(I14=10,"Alto (10)",IF(I14=12,"Alto (12)",IF(I14=15,"Alto (15)",IF(I14=16,"Alto (16)",IF(I14=20,"Muito Alto (20)",IF(I14=25,"Muito Alto (25)","Erro")))))))))))))) -> Alto (15)
B15: R.OPE.08 | C15: Operação/ Estoques/ Manutenção | D15: Risco de equipamentos (ex.: balança, trena, arqueação do tanque, termômetros e Enraf) serem calibrados incorretamente, possibilitando a saída ou entrada de mercadorias diferentes das registradas, com objetivo de obtenção de vantagem indevida. | E15: Recomendamos a elaboração de uma rotina periódica de revisão e manutenção dos equipamentos para garantir a integridade das medidas reportadas. | F15: 5 - Muito Alto | G15: "Propriedade intelectual e industrial" e "Fraude" | H15: 3 - Possível | I15: =(IF(F15="1 - Muito Baixo",1,IF(F15="2 - Baixo",2,IF(F15="3 - Médio",3,IF(F15="4 - Alto",4,IF(F15="5 - Muito Alto",5,0))))))*(IF(H15="1 - Raramente",1,IF(H15="2 - Pouco Provável",2,IF(H15="3 - Possível",3,IF(H15="4 - Muito provável",4,IF(H15="5 - Quase Certa ocorrência",5,0)))))) -> 15 | J15: =IF(I15=1,"Baixo (1)",IF(I15=2,"Baixo (2)",IF(I15=3,"Baixo (3)",IF(I15=4,"Baixo (4)",IF(I15=5,"Médio (5)",IF(I15=6,"Médio (6)",IF(I15=8,"Médio (8)",IF(I15=9,"Médio (9)",IF(I15=10,"Alto (10)",IF(I15=12,"Alto (12)",IF(I15=15,"Alto (15)",IF(I15=16,"Alto (16)",IF(I15=20,"Muito Alto (20)",IF(I15=25,"Muito Alto (25)","Erro")))))))))))))) -> Alto (15)

Sheet Qualidade
F6: Análise de Risco
B7: Ref. | C7: Processo | D7: Risco | E7: Recomendação | F7: Impacto | G7: Classificação do Risco | H7: Probabilidade | I7: Cálculo | J7: Análise de Risco
B8: R.QUA.01 | C8: Qualidade | D8: Risco de fraude na obtenção e manutenção das certificações ISOs requeridas em cláusulas contratuais com clientes (órgão público). | E8: Recomendamos que todo o processo para obtenção e manutenção dos certificados (ex.: ISO's) requerido por agentes públicos ou órgãos reguladores (que possuam qualquer tipo de relação com a DECAL Brasil) seja acompanhado por membros da equipe do comitê de compliance para garantir que nenhuma ação considerada como ilícita ou indevida (ex.: pagamento de valores indevidos com intenção de obtenção de vantagem indevida) ocorra. | F8: 1 - Muito Baixo | G8: Meio Ambiente e Segurança do trabalho | H8: 4 - Muito provável | I8: =(IF(F8="1 - Muito Baixo",1,IF(F8="2 - Baixo",2,IF(F8="3 - Médio",3,IF(F8="4 - Alto",4,IF(F8="5 - Muito Alto",5,0))))))*(IF(H8="1 - Raramente",1,IF(H8="2 - Pouco Provável",2,IF(H8="3 - Possível",3,IF(H8="4 - Muito provável",4,IF(H8="5 - Quase Certa ocorrência",5,0)))))) -> 4 | J8: =IF(I8=1,"Baixo (1)",IF(I8=2,"Baixo (2)",IF(I8=3,"Baixo (3)",IF(I8=4,"Baixo (4)",IF(I8=5,"Médio (5)",IF(I8=6,"Médio (6)",IF(I8=8,"Médio (8)",IF(I8=9,"Médio (9)",IF(I8=10,"Alto (10)",IF(I8=12,"Alto (12)",IF(I8=15,"Alto (15)",IF(I8=16,"Alto (16)",IF(I8=20,"Muito Alto (20)",IF(I8=25,"Muito Alto (25)","Erro")))))))))))))) -> Baixo (4)
B9: R.QUA.02 | C9: Qualidade | D9: Risco de manipulação dos resultados nas atividades de investigação ou fiscalização de órgãos, entidades ou agentes públicos requeridas nos contratos de prestação de serviços. | E9: Recomendamos que todo o processo de investigação ou fiscalização, requerido por agentes públicos ou órgãos reguladores, tenha o acompanhamento da área envolvida e do comitê de compliance, para garantir que nenhuma ação considerada como ilícita ou indevida (ex.: pagamento de valores indevidos com intenção de obtenção de vantagem indevida) ocorra. | F9: 1 - Muito Baixo | G9: Meio Ambiente e Segurança do trabalho | H9: 4 - Muito provável | I9: =(IF(F9="1 - Muito Baixo",1,IF(F9="2 - Baixo",2,IF(F9="3 - Médio",3,IF(F9="4 - Alto",4,IF(F9="5 - Muito Alto",5,0))))))*(IF(H9="1 - Raramente",1,IF(H9="2 - Pouco Provável",2,IF(H9="3 - Possível",3,IF(H9="4 - Muito provável",4,IF(H9="5 - Quase Certa ocorrência",5,0)))))) -> 4 | J9: =IF(I9=1,"Baixo (1)",IF(I9=2,"Baixo (2)",IF(I9=3,"Baixo (3)",IF(I9=4,"Baixo (4)",IF(I9=5,"Médio (5)",IF(I9=6,"Médio (6)",IF(I9=8,"Médio (8)",IF(I9=9,"Médio (9)",IF(I9=10,"Alto (10)",IF(I9=12,"Alto (12)",IF(I9=15,"Alto (15)",IF(I9=16,"Alto (16)",IF(I9=20,"Muito Alto (20)",IF(I9=25,"Muito Alto (25)","Erro")))))))))))))) -> Baixo (4)

Sheet Recursos Humanos
F6: Análise de Risco
B7: Ref. | C7: Processo | D7: Risco | E7: Recomendação | F7: Impacto | G7: Classificação do Risco | H7: Probabilidade | I7: Cálculo | J7: Análise de Risco
B8: R.RH.01 | C8: Recursos Humanos | D8: Risco de contratação de ex-agentes públicos dentro do período de quarentena, conforme a Lei 12.813/13 e a Lei Anticorrupção. | E8: Recomendamos que, no momento da contratação de qualquer ex-agente público como funcionário, seja avaliado o cumprimento do período mínimo de impedimento, conforme definido em lei (12.813/13 e Lei Anticorrupção). | F8: 4 - Alto | G8: Crimes contra a privacidade (funcionários) | H8: 3 - Possível | I8: =(IF(F8="1 - Muito Baixo",1,IF(F8="2 - Baixo",2,IF(F8="3 - Médio",3,IF(F8="4 - Alto",4,IF(F8="5 - Muito Alto",5,0))))))*(IF(H8="1 - Raramente",1,IF(H8="2 - Pouco Provável",2,IF(H8="3 - Possível",3,IF(H8="4 - Muito provável",4,IF(H8="5 - Quase Certa ocorrência",5,0)))))) -> 12 | J8: =IF(I8=1,"Baixo (1)",IF(I8=2,"Baixo (2)",IF(I8=3,"Baixo (3)",IF(I8=4,"Baixo (4)",IF(I8=5,"Médio (5)",IF(I8=6,"Médio (6)",IF(I8=8,"Médio (8)",IF(I8=9,"Médio (9)",IF(I8=10,"Alto (10)",IF(I8=12,"Alto (12)",IF(I8=15,"Alto (15)",IF(I8=16,"Alto (16)",IF(I8=20,"Muito Alto (20)",IF(I8=25,"Muito Alto (25)","Erro")))))))))))))) -> Alto (12)
B9: R.RH.02 | C9: Recursos Humanos | D9: Risco de contratação de agentes públicos pela DECAL Brasil com o objetivo de obtenção de vantagem ou benefício indevidos. | E9: Recomendamos que, quando um agente público ou ex-agente público for contratado, a equipe do comitê de compliance da DECAL Brasil acompanhe todo o processo de avaliação e aprovação para contratação, prestação do serviço e do pagamento realizado. | F9: 4 - Alto | G9: Crimes contra a privacidade (funcionários) | H9: 3 - Possível | I9: =(IF(F9="1 - Muito Baixo",1,IF(F9="2 - Baixo",2,IF(F9="3 - Médio",3,IF(F9="4 - Alto",4,IF(F9="5 - Muito Alto",5,0))))))*(IF(H9="1 - Raramente",1,IF(H9="2 - Pouco Provável",2,IF(H9="3 - Possível",3,IF(H9="4 - Muito provável",4,IF(H9="5 - Quase Certa ocorrência",5,0)))))) -> 12 | J9: =IF(I9=1,"Baixo (1)",IF(I9=2,"Baixo (2)",IF(I9=3,"Baixo (3)",IF(I9=4,"Baixo (4)",IF(I9=5,"Médio (5)",IF(I9=6,"Médio (6)",IF(I9=8,"Médio (8)",IF(I9=9,"Médio (9)",IF(I9=10,"Alto (10)",IF(I9=12,"Alto (12)",IF(I9=15,"Alto (15)",IF(I9=16,"Alto (16)",IF(I9=20,"Muito Alto (20)",IF(I9=25,"Muito Alto (25)","Erro")))))))))))))) -> Alto (12)
B10: R.RH.03 | C10: Recursos Humanos | D10: Risco de contratação de familiares de agentes públicos ou ex-agentes públicos com o objetivo de obtenção de vantagem ou benefício indevido. | E10: Recomendamos que, no momento da contratação de qualquer funcionário, seja realizada uma avaliação prévia de independência deste com qualquer agente público ou ex-agente público com relacionamento com a DECAL Brasil e, caso seja identificado algum caso, o comitê de compliance deve ser envolvido no processo de aprovação da contratação. | F10: 4 - Alto | G10: Crimes contra a privacidade (funcionários) | H10: 3 - Possível | I10: =(IF(F10="1 - Muito Baixo",1,IF(F10="2 - Baixo",2,IF(F10="3 - Médio",3,IF(F10="4 - Alto",4,IF(F10="5 - Muito Alto",5,0))))))*(IF(H10="1 - Raramente",1,IF(H10="2 - Pouco Provável",2,IF(H10="3 - Possível",3,IF(H10="4 - Muito provável",4,IF(H10="5 - Quase Certa ocorrência",5,0)))))) -> 12 | J10: =IF(I10=1,"Baixo (1)",IF(I10=2,"Baixo (2)",IF(I10=3,"Baixo (3)",IF(I10=4,"Baixo (4)",IF(I10=5,"Médio (5)",IF(I10=6,"Médio (6)",IF(I10=8,"Médio (8)",IF(I10=9,"Médio (9)",IF(I10=10,"Alto (10)",IF(I10=12,"Alto (12)",IF(I10=15,"Alto (15)",IF(I10=16,"Alto (16)",IF(I10=20,"Muito Alto (20)",IF(I10=25,"Muito Alto (25)","Erro")))))))))))))) -> Alto (12)
B11: R.RH.04 | C11: Recursos Humanos | D11: Risco na contratação de terceirizados que possuem relacionamento com agentes públicos ou ex-agentes públicos com o objetivo de obtenção de vantagem ou benefício indevido. | E11: Recomendamos que, no momento da contratação de qualquer terceirizado, seja realizada uma avaliação prévia de independência deste com qualquer agente público ou ex-agente público com relacionamento com a DECAL Brasil e, caso seja identificado algum caso, o comitê de compliance deve ser envolvido no processo de aprovação da contratação. | F11: 4 - Alto | G11: Crimes contra a privacidade (funcionários) | H11: 3 - Possível | I11: =(IF(F11="1 - Muito Baixo",1,IF(F11="2 - Baixo",2,IF(F11="3 - Médio",3,IF(F11="4 - Alto",4,IF(F11="5 - Muito Alto",5,0))))))*(IF(H11="1 - Raramente",1,IF(H11="2 - Pouco Provável",2,IF(H11="3 - Possível",3,IF(H11="4 - Muito provável",4,IF(H11="5 - Quase Certa ocorrência",5,0)))))) -> 12 | J11: =IF(I11=1,"Baixo (1)",IF(I11=2,"Baixo (2)",IF(I11=3,"Baixo (3)",IF(I11=4,"Baixo (4)",IF(I11=5,"Médio (5)",IF(I11=6,"Médio (6)",IF(I11=8,"Médio (8)",IF(I11=9,"Médio (9)",IF(I11=10,"Alto (10)",IF(I11=12,"Alto (12)",IF(I11=15,"Alto (15)",IF(I11=16,"Alto (16)",IF(I11=20,"Muito Alto (20)",IF(I11=25,"Muito Alto (25)","Erro")))))))))))))) -> Alto (12)
B12: R.RH.05 | C12: Recursos Humanos | D12: Risco de ausência de treinamentos de compliance para todos os funcionários e terceirizados da empresa. | E12: Recomendamos a implementação de uma rotina periódica (ex.: anual) para realização dos treinamentos de compliance para todos os membros da DECAL Brasil, com grade diferenciada para aqueles que possuem relacionamento direto com agentes públicos. | F12: 5 - Muito Alto | G12: Fraude e Corrupção | H12: 3 - Possível | I12: =(IF(F12="1 - Muito Baixo",1,IF(F12="2 - Baixo",2,IF(F12="3 - Médio",3,IF(F12="4 - Alto",4,IF(F12="5 - Muito Alto",5,0))))))*(IF(H12="1 - Raramente",1,IF(H12="2 - Pouco Provável",2,IF(H12="3 - Possível",3,IF(H12="4 - Muito provável",4,IF(H12="5 - Quase Certa ocorrência",5,0)))))) -> 15 | J12: =IF(I12=1,"Baixo (1)",IF(I12=2,"Baixo (2)",IF(I12=3,"Baixo (3)",IF(I12=4,"Baixo (4)",IF(I12=5,"Médio (5)",IF(I12=6,"Médio (6)",IF(I12=8,"Médio (8)",IF(I12=9,"Médio (9)",IF(I12=10,"Alto (10)",IF(I12=12,"Alto (12)",IF(I12=15,"Alto (15)",IF(I12=16,"Alto (16)",IF(I12=20,"Muito Alto (20)",IF(I12=25,"Muito Alto (25)","Erro")))))))))))))) -> Alto (15)
B13: R.RH.06 | C13: Recursos Humanos | D13: Risco de ausência de treinamentos de compliance para a equipe do comitê de compliance. | E13: Recomendamos a implementação de uma rotina periódica (ex.: anual) para realização dos treinamentos de compliance para todos os membros do comitê de compliance da DECAL Brasil. | F13: 5 - Muito Alto | G13: Fraude e Corrupção | H13: 3 - Possível | I13: =(IF(F13="1 - Muito Baixo",1,IF(F13="2 - Baixo",2,IF(F13="3 - Médio",3,IF(F13="4 - Alto",4,IF(F13="5 - Muito Alto",5,0))))))*(IF(H13="1 - Raramente",1,IF(H13="2 - Pouco Provável",2,IF(H13="3 - Possível",3,IF(H13="4 - Muito provável",4,IF(H13="5 - Quase Certa ocorrência",5,0)))))) -> 15 | J13: =IF(I13=1,"Baixo (1)",IF(I13=2,"Baixo (2)",IF(I13=3,"Baixo (3)",IF(I13=4,"Baixo (4)",IF(I13=5,"Médio (5)",IF(I13=6,"Médio (6)",IF(I13=8,"Médio (8)",IF(I13=9,"Médio (9)",IF(I13=10,"Alto (10)",IF(I13=12,"Alto (12)",IF(I13=15,"Alto (15)",IF(I13=16,"Alto (16)",IF(I13=20,"Muito Alto (20)",IF(I13=25,"Muito Alto (25)","Erro")))))))))))))) -> Alto (15)

Sheet Tecnologia da Informação
F6: Análise de Risco
B7: Ref. | C7: Processo | D7: Risco | E7: Recomendação | F7: Impacto | G7: Classificação do Risco | H7: Probabilidade | I7: Cálculo | J7: Análise de Risco
B8: R.TI.01 | C8: TI | D8: Risco de transgressão das regras de segurança da informação por funcionários, possibilitando o vazamento de dados de agentes públicos, ex-agentes públicos, órgãos regulamentares ou empresas privadas. | E8: Recomendamos que periodicamente (ex.: semestral) todos os funcionários da DECAL Brasil tenham que atestar pleno conhecimento e conformidade com as regras de segurança da informação da empresa. | F8: 5 - Muito Alto | G8: Delitos tecnológicos | H8: 2 - Pouco provável | I8: =(IF(F8="1 - Muito Baixo",1,IF(F8="2 - Baixo",2,IF(F8="3 - Médio",3,IF(F8="4 - Alto",4,IF(F8="5 - Muito Alto",5,0))))))*(IF(H8="1 - Raramente",1,IF(H8="2 - Pouco Provável",2,IF(H8="3 - Possível",3,IF(H8="4 - Muito provável",4,IF(H8="5 - Quase Certa ocorrência",5,0)))))) -> 10 | J8: =IF(I8=1,"Baixo (1)",IF(I8=2,"Baixo (2)",IF(I8=3,"Baixo (3)",IF(I8=4,"Baixo (4)",IF(I8=5,"Médio (5)",IF(I8=6,"Médio (6)",IF(I8=8,"Médio (8)",IF(I8=9,"Médio (9)",IF(I8=10,"Alto (10)",IF(I8=12,"Alto (12)",IF(I8=15,"Alto (15)",IF(I8=16,"Alto (16)",IF(I8=20,"Muito Alto (20)",IF(I8=25,"Muito Alto (25)","Erro")))))))))))))) -> Alto (10)
B9: R.TI.02 | C9: TI | D9: Risco de acessos indevidos às transações realizadas diretamente nos sistemas (ex.: pagamentos, compras, recebimentos, etc.) relacionadas a informações de agentes públicos, ex-agentes públicos, órgãos regulamentares ou empresas privadas, podendo ocasionar em edição ou deleção indevida de informações. | E9: Recomendamos que todos os acessos aos sistemas que tenham processos de agentes públicos (ex.: registro de pagamentos para órgãos públicos, contabilização de dados) tenham seus acessos restritos, revisados periodicamente (ex.: trimestral) e monitorados pela equipe de TI e áreas responsáveis. | F9: 5 - Muito Alto | G9: Delitos tecnológicos | H9: 2 - Pouco provável | I9: =(IF(F9="1 - Muito Baixo",1,IF(F9="2 - Baixo",2,IF(F9="3 - Médio",3,IF(F9="4 - Alto",4,IF(F9="5 - Muito Alto",5,0))))))*(IF(H9="1 - Raramente",1,IF(H9="2 - Pouco Provável",2,IF(H9="3 - Possível",3,IF(H9="4 - Muito provável",4,IF(H9="5 - Quase Certa ocorrência",5,0)))))) -> 10 | J9: =IF(I9=1,"Baixo (1)",IF(I9=2,"Baixo (2)",IF(I9=3,"Baixo (3)",IF(I9=4,"Baixo (4)",IF(I9=5,"Médio (5)",IF(I9=6,"Médio (6)",IF(I9=8,"Médio (8)",IF(I9=9,"Médio (9)",IF(I9=10,"Alto (10)",IF(I9=12,"Alto (12)",IF(I9=15,"Alto (15)",IF(I9=16,"Alto (16)",IF(I9=20,"Muito Alto (20)",IF(I9=25,"Muito Alto (25)","Erro")))))))))))))) -> Alto (10)
B10: R.TI.03 | C10: TI | D10: Risco de acessos indevidos à base de dados (banco de dados) de sistemas relacionados a informações de agentes públicos, ex-agentes públicos, órgãos regulamentares ou empresas privadas, podendo ocasionar em edição ou deleção indevida de informações. | E10: Recomendamos que o acesso direto para a base de dados (banco de dados) que envolvam qualquer relação com agentes públicos, ex-agentes públicos ou órgãos regulamentares, seja restrito e monitorado pela equipe de TI. | F10: 5 - Muito Alto | G10: Delitos tecnológicos | H10: 2 - Pouco provável | I10: =(IF(F10="1 - Muito Baixo",1,IF(F10="2 - Baixo",2,IF(F10="3 - Médio",3,IF(F10="4 - Alto",4,IF(F10="5 - Muito Alto",5,0))))))*(IF(H10="1 - Raramente",1,IF(H10="2 - Pouco Provável",2,IF(H10="3 - Possível",3,IF(H10="4 - Muito provável",4,IF(H10="5 - Quase Certa ocorrência",5,0)))))) -> 10 | J10: =IF(I10=1,"Baixo (1)",IF(I10=2,"Baixo (2)",IF(I10=3,"Baixo (3)",IF(I10=4,"Baixo (4)",IF(I10=5,"Médio (5)",IF(I10=6,"Médio (6)",IF(I10=8,"Médio (8)",IF(I10=9,"Médio (9)",IF(I10=10,"Alto (10)",IF(I10=12,"Alto (12)",IF(I10=15,"Alto (15)",IF(I10=16,"Alto (16)",IF(I10=20,"Muito Alto (20)",IF(I10=25,"Muito Alto (25)","Erro")))))))))))))) -> Alto (10)

Sheet Vendas e Contas a Receber
F6: Análise de Risco
B7: Ref. | C7: Processo | D7: Risco | E7: Recomendação | F7: Impacto | G7: Classificação do Risco | H7: Probabilidade | I7: Cálculo | J7: Análise de Risco
B8: R.VEN.01 | C8: Vendas e Contas a Receber | D8: Risco de conflitos de interesse nas negociações com clientes. | E8: Recomendamos que todas as negociações realizadas com agentes públicos e grandes clientes da DECAL Brasil sejam realizadas por mais de um membro da empresa, com acompanhamento direto de membros do comitê de compliance, garantindo que um mesmo funcionário não ocupe duas posições (ex.: gerente comercial e membro do comitê de compliance). Recomendamos a definição de alçadas de negociação onde a aprovação da equipe de compliance seja requerida. | F8: 5 - Muito Alto | G8: "Corrupção" e "Clientes e Fornecedores" | H8: 4 - Muito provável | I8: =(IF(F8="1 - Muito Baixo",1,IF(F8="2 - Baixo",2,IF(F8="3 - Médio",3,IF(F8="4 - Alto",4,IF(F8="5 - Muito Alto",5,0))))))*(IF(H8="1 - Raramente",1,IF(H8="2 - Pouco Provável",2,IF(H8="3 - Possível",3,IF(H8="4 - Muito provável",4,IF(H8="5 - Quase Certa ocorrência",5,0)))))) -> 20 | J8: =IF(I8=1,"Baixo (1)",IF(I8=2,"Baixo (2)",IF(I8=3,"Baixo (3)",IF(I8=4,"Baixo (4)",IF(I8=5,"Médio (5)",IF(I8=6,"Médio (6)",IF(I8=8,"Médio (8)",IF(I8=9,"Médio (9)",IF(I8=10,"Alto (10)",IF(I8=12,"Alto (12)",IF(I8=15,"Alto (15)",IF(I8=16,"Alto (16)",IF(I8=20,"Muito Alto (20)",IF(I8=25,"Muito Alto (25)","Erro")))))))))))))) -> Muito Alto (20)
B9: R.VEN.02 | C9: Vendas e Contas a Receber | D9: Risco de transgressão das regras no processo licitatório, conforme definido na Lei Anticorrupção. | E9: Recomendamos que, quando a DECAL Brasil participar de um processo licitatório com agente público, o comitê de compliance deve acompanhar todas as etapas do processo para garantir o atendimento a todas as regras da licitação. | F9: 5 - Muito Alto | G9: "Corrupção" e "Clientes e Fornecedores" | H9: 4 - Muito provável | I9: =(IF(F9="1 - Muito Baixo",1,IF(F9="2 - Baixo",2,IF(F9="3 - Médio",3,IF(F9="4 - Alto",4,IF(F9="5 - Muito Alto",5,0))))))*(IF(H9="1 - Raramente",1,IF(H9="2 - Pouco Provável",2,IF(H9="3 - Possível",3,IF(H9="4 - Muito provável",4,IF(H9="5 - Quase Certa ocorrência",5,0)))))) -> 20 | J9: =IF(I9=1,"Baixo (1)",IF(I9=2,"Baixo (2)",IF(I9=3,"Baixo (3)",IF(I9=4,"Baixo (4)",IF(I9=5,"Médio (5)",IF(I9=6,"Médio (6)",IF(I9=8,"Médio (8)",IF(I9=9,"Médio (9)",IF(I9=10,"Alto (10)",IF(I9=12,"Alto (12)",IF(I9=15,"Alto (15)",IF(I9=16,"Alto (16)",IF(I9=20,"Muito Alto (20)",IF(I9=25,"Muito Alto (25)","Erro")))))))))))))) -> Muito Alto (20)

Sheet Análise de Risco
C8: Análise de Risco
D9: Impacto
C10: Probabilidade | D10: 1 - Muito Pequeno | E10: 2 - Pequeno | F10: 3 - Moderado | G10: 4 - Grande | H10: 5 - Significante
C11: 5 - Ocorrência quase certa | D11: Médio (5) | E11: Alto (10) | F11: Alto (15) | G11: Muito Alto (20) | H11: Muito Alto (25)
C12: 4 - Muito provável | D12: Baixo (4) | E12: Médio (6) | F12: Alto (12) | G12: Alto (16) | H12: Muito Alto (20)
C13: 3 - Possível | D13: Baixo (3) | E13: Médio (5) | F13: Médio (9) | G13: Alto (12) | H13: Alto (15)
C14: 2 - Pouco provável | D14: Baixo (2) | E14: Baixo (4) | F14: Médio (6) | G14: Médio (8) | H14: Alto (10)
C15: 1 - Remota | D15: Baixo (1) | E15: Baixo (2) | F15: Baixo (3) | G15: Baixo (4) | H15: Médio (5)
C18: Classificação do risco | D18: Probabilidade
C19: Corrupção | D19: 3 - Possível
C20: Delitos tecnológicos | D20: 2 - Pouco provável
C21: Propriedade intelectual e industrial | D21: 3 - Possível
C22: Agentes públicos | D22: 4 - Muito provável
C23: Clientes e Fornecedores | D23: 4 - Muito provável
C24: Lavagem de dinheiro | D24: 1 - Remota
